<sdf version='1.7'>
  <world name='default'>
    <light name='sun' type='directional'>
      <cast_shadows>1</cast_shadows>
      <pose>0 0 10 0 -0 0</pose>
      <diffuse>0.8 0.8 0.8 1</diffuse>
      <specular>0.2 0.2 0.2 1</specular>
      <attenuation>
        <range>1000</range>
        <constant>0.9</constant>
        <linear>0.01</linear>
        <quadratic>0.001</quadratic>
      </attenuation>
      <direction>-0.5 0.1 -0.9</direction>
      <spot>
        <inner_angle>0</inner_angle>
        <outer_angle>0</outer_angle>
        <falloff>0</falloff>
      </spot>
    </light>
    <model name='ground_plane'>
      <static>1</static>
      <link name='link'>
        <collision name='collision'>
          <geometry>
            <plane>
              <normal>0 0 1</normal>
              <size>100 100</size>
            </plane>
          </geometry>
          <surface>
            <contact>
              <collide_bitmask>65535</collide_bitmask>
              <ode/>
            </contact>
            <friction>
              <ode>
                <mu>100</mu>
                <mu2>50</mu2>
              </ode>
              <torsional>
                <ode/>
              </torsional>
            </friction>
            <bounce/>
          </surface>
          <max_contacts>10</max_contacts>
        </collision>
        <visual name='visual'>
          <cast_shadows>0</cast_shadows>
          <geometry>
            <plane>
              <normal>0 0 1</normal>
              <size>100 100</size>
            </plane>
          </geometry>
          <material>
            <script>
              <uri>file://media/materials/scripts/gazebo.material</uri>
              <name>Gazebo/Grey</name>
            </script>
          </material>
        </visual>
        <self_collide>0</self_collide>
        <enable_wind>0</enable_wind>
        <kinematic>0</kinematic>
      </link>
    </model>
    <gravity>0 0 -9.8</gravity>
    <magnetic_field>6e-06 2.3e-05 -4.2e-05</magnetic_field>
    <atmosphere type='adiabatic'/>
    <physics type='ode'>
      <max_step_size>0.001</max_step_size>
      <real_time_factor>1</real_time_factor>
      <real_time_update_rate>1000</real_time_update_rate>
    </physics>
    <scene>
      <ambient>0.4 0.4 0.4 1</ambient>
      <background>0.7 0.7 0.7 1</background>
      <shadows>1</shadows>
    </scene>
    <audio>
      <device>default</device>
    </audio>
    <wind/>
    <spherical_coordinates>
      <surface_model>EARTH_WGS84</surface_model>
      <latitude_deg>0</latitude_deg>
      <longitude_deg>0</longitude_deg>
      <elevation>0</elevation>
      <heading_deg>0</heading_deg>
    </spherical_coordinates>
    <model name='spider_bot'>
      <link name='base_link'>
        <inertial>
          <pose>0 0 0 0 -0 0</pose>
          <mass>1</mass>
          <inertia>
            <ixx>0.02</ixx>
            <ixy>0</ixy>
            <ixz>0</ixz>
            <iyy>0.02</iyy>
            <iyz>0</iyz>
            <izz>0.04</izz>
          </inertia>
        </inertial>
        <collision name='base_link_collision'>
          <pose>0 0 0 0 -0 0</pose>
          <geometry>
            <box>
              <size>0.15 0.15 0.05</size>
            </box>
          </geometry>
          <surface>
            <contact>
              <ode/>
            </contact>
            <friction>
              <ode>
                <mu>0.2</mu>
                <mu2>0.2</mu2>
              </ode>
              <torsional>
                <ode/>
              </torsional>
            </friction>
            <bounce/>
          </surface>
          <max_contacts>10</max_contacts>
        </collision>
        <visual name='base_link_visual'>
          <pose>0 0 0 0 -0 0</pose>
          <geometry>
            <box>
              <size>0.15 0.15 0.05</size>
            </box>
          </geometry>
          <material>
            <script>
              <name>Gazebo/Blue</name>
              <uri>file://media/materials/scripts/gazebo.material</uri>
            </script>
          </material>
        </visual>
        <visual name='base_link_fixed_joint_lump__camera_link_visual_1'>
          <pose>0.08 0 0.025 0 -0 0</pose>
          <geometry>
            <box>
              <size>0.02 0.05 0.02</size>
            </box>
          </geometry>
          <material>
            <script>
              <name>Gazebo/Black</name>
              <uri>file://media/materials/scripts/gazebo.material</uri>
            </script>
          </material>
        </visual>
        <self_collide>0</self_collide>
        <sensor name='depth_camera' type='depth'>
          <update_rate>30</update_rate>
          <camera name='head'>
            <horizontal_fov>1.39626</horizontal_fov>
            <image>
              <width>640</width>
              <height>480</height>
              <format>R8G8B8</format>
            </image>
            <clip>
              <near>0.05</near>
              <far>3</far>
            </clip>
          </camera>
          <plugin name='camera_controller' filename='libgazebo_ros_camera.so'>
            <ros>
              <namespace>/</namespace>
              <remapping>custom_camera/image_raw:=camera/image_raw</remapping>
              <remapping>custom_camera/depth/image_raw:=camera/depth/image_raw</remapping>
            </ros>
            <camera_name>camera</camera_name>
            <frame_name>camera_link</frame_name>
          </plugin>
          <pose>0.08 0 0.025 0 -0 0</pose>
        </sensor>
        <enable_wind>0</enable_wind>
        <kinematic>0</kinematic>
      </link>
      <joint name='joint1' type='revolute'>
        <pose relative_to='base_link'>0.1 0.1 0 0 -0 0.785</pose>
        <parent>base_link</parent>
        <child>l1_c</child>
        <axis>
          <xyz>0 0 1</xyz>
          <limit>
            <lower>-1.57</lower>
            <upper>1.57</upper>
            <effort>10</effort>
            <velocity>1</velocity>
          </limit>
          <dynamics>
            <damping>1.5</damping>
            <friction>0.1</friction>
            <spring_reference>0</spring_reference>
            <spring_stiffness>0</spring_stiffness>
          </dynamics>
        </axis>
      </joint>
      <link name='l1_c'>
        <pose relative_to='joint1'>0 0 0 0 -0 0</pose>
        <inertial>
          <pose>0 0 0 0 -0 0</pose>
          <mass>0.1</mass>
          <inertia>
            <ixx>0.01</ixx>
            <ixy>0</ixy>
            <ixz>0</ixz>
            <iyy>0.01</iyy>
            <iyz>0</iyz>
            <izz>0.01</izz>
          </inertia>
        </inertial>
        <collision name='l1_c_collision'>
          <pose>0.02 0 0 0 -0 0</pose>
          <geometry>
            <box>
              <size>0.04 0.02 0.02</size>
            </box>
          </geometry>
          <max_contacts>10</max_contacts>
          <surface>
            <contact>
              <ode/>
            </contact>
            <bounce/>
            <friction>
              <torsional>
                <ode/>
              </torsional>
              <ode/>
            </friction>
          </surface>
        </collision>
        <visual name='l1_c_visual'>
          <pose>0.02 0 0 0 -0 0</pose>
          <geometry>
            <box>
              <size>0.04 0.02 0.02</size>
            </box>
          </geometry>
        </visual>
        <self_collide>0</self_collide>
        <enable_wind>0</enable_wind>
        <kinematic>0</kinematic>
      </link>
      <joint name='joint2' type='revolute'>
        <pose relative_to='l1_c'>0.04 0 0 0 -0.785 0</pose>
        <parent>l1_c</parent>
        <child>l1_f</child>
        <axis>
          <xyz>0 -1 0</xyz>
          <limit>
            <lower>-3.14</lower>
            <upper>3.14</upper>
            <effort>10</effort>
            <velocity>1</velocity>
          </limit>
          <dynamics>
            <damping>1.5</damping>
            <friction>0.1</friction>
            <spring_reference>0</spring_reference>
            <spring_stiffness>0</spring_stiffness>
          </dynamics>
        </axis>
      </joint>
      <link name='l1_f'>
        <pose relative_to='joint2'>0 0 0 0 -0 0</pose>
        <inertial>
          <pose>0 0 0 0 -0 0</pose>
          <mass>0.1</mass>
          <inertia>
            <ixx>0.01</ixx>
            <ixy>0</ixy>
            <ixz>0</ixz>
            <iyy>0.01</iyy>
            <iyz>0</iyz>
            <izz>0.01</izz>
          </inertia>
        </inertial>
        <collision name='l1_f_collision'>
          <pose>0.04 0 0 0 -0 0</pose>
          <geometry>
            <box>
              <size>0.08 0.02 0.02</size>
            </box>
          </geometry>
          <max_contacts>10</max_contacts>
          <surface>
            <contact>
              <ode/>
            </contact>
            <bounce/>
            <friction>
              <torsional>
                <ode/>
              </torsional>
              <ode/>
            </friction>
          </surface>
        </collision>
        <visual name='l1_f_visual'>
          <pose>0.04 0 0 0 -0 0</pose>
          <geometry>
            <box>
              <size>0.08 0.02 0.02</size>
            </box>
          </geometry>
        </visual>
        <self_collide>0</self_collide>
        <enable_wind>0</enable_wind>
        <kinematic>0</kinematic>
      </link>
      <joint name='joint3' type='revolute'>
        <pose relative_to='l1_f'>0.08 0 0 0 1.57 0</pose>
        <parent>l1_f</parent>
        <child>l1_t</child>
        <axis>
          <xyz>0 -1 0</xyz>
          <limit>
            <lower>-3.14</lower>
            <upper>3.14</upper>
            <effort>10</effort>
            <velocity>1</velocity>
          </limit>
          <dynamics>
            <damping>1.5</damping>
            <friction>0.1</friction>
            <spring_reference>0</spring_reference>
            <spring_stiffness>0</spring_stiffness>
          </dynamics>
        </axis>
      </joint>
      <link name='l1_t'>
        <pose relative_to='joint3'>0 0 0 0 -0 0</pose>
        <inertial>
          <pose>0 0 0 0 -0 0</pose>
          <mass>0.2</mass>
          <inertia>
            <ixx>0.001</ixx>
            <ixy>0</ixy>
            <ixz>0</ixz>
            <iyy>0.001</iyy>
            <iyz>0</iyz>
            <izz>0.001</izz>
          </inertia>
        </inertial>
        <collision name='l1_t_collision'>
          <pose>0.07 0 0 0 -0 0</pose>
          <geometry>
            <box>
              <size>0.14 0.04 0.04</size>
            </box>
          </geometry>
          <surface>
            <contact>
              <ode>
                <kp>10000</kp>
                <kd>10</kd>
              </ode>
            </contact>
            <friction>
              <ode>
                <mu>2</mu>
                <mu2>2</mu2>
              </ode>
              <torsional>
                <ode/>
              </torsional>
            </friction>
            <bounce/>
          </surface>
          <max_contacts>10</max_contacts>
        </collision>
        <visual name='l1_t_visual'>
          <pose>0.07 0 0 0 -0 0</pose>
          <geometry>
            <box>
              <size>0.1 0.04 0.04</size>
            </box>
          </geometry>
        </visual>
        <visual name='l1_t_visual_1'>
          <pose>0.02 0 0 1.5708 -0 0</pose>
          <geometry>
            <cylinder>
              <length>0.04</length>
              <radius>0.02</radius>
            </cylinder>
          </geometry>
        </visual>
        <visual name='l1_t_visual_2'>
          <pose>0.12 0 0 1.5708 -0 0</pose>
          <geometry>
            <cylinder>
              <length>0.04</length>
              <radius>0.02</radius>
            </cylinder>
          </geometry>
        </visual>
        <self_collide>0</self_collide>
        <enable_wind>0</enable_wind>
        <kinematic>0</kinematic>
      </link>
      <joint name='joint10' type='revolute'>
        <pose relative_to='base_link'>-0.1 -0.1 0 0 0 -2.355</pose>
        <parent>base_link</parent>
        <child>l4_c</child>
        <axis>
          <xyz>0 0 1</xyz>
          <limit>
            <lower>-1.57</lower>
            <upper>1.57</upper>
            <effort>10</effort>
            <velocity>1</velocity>
          </limit>
          <dynamics>
            <damping>1.5</damping>
            <friction>0.1</friction>
            <spring_reference>0</spring_reference>
            <spring_stiffness>0</spring_stiffness>
          </dynamics>
        </axis>
      </joint>
      <link name='l4_c'>
        <pose relative_to='joint10'>0 0 0 0 -0 0</pose>
        <inertial>
          <pose>0 0 0 0 -0 0</pose>
          <mass>0.1</mass>
          <inertia>
            <ixx>0.01</ixx>
            <ixy>0</ixy>
            <ixz>0</ixz>
            <iyy>0.01</iyy>
            <iyz>0</iyz>
            <izz>0.01</izz>
          </inertia>
        </inertial>
        <collision name='l4_c_collision'>
          <pose>0.02 0 0 0 -0 0</pose>
          <geometry>
            <box>
              <size>0.04 0.02 0.02</size>
            </box>
          </geometry>
          <max_contacts>10</max_contacts>
          <surface>
            <contact>
              <ode/>
            </contact>
            <bounce/>
            <friction>
              <torsional>
                <ode/>
              </torsional>
              <ode/>
            </friction>
          </surface>
        </collision>
        <visual name='l4_c_visual'>
          <pose>0.02 0 0 0 -0 0</pose>
          <geometry>
            <box>
              <size>0.04 0.02 0.02</size>
            </box>
          </geometry>
        </visual>
        <self_collide>0</self_collide>
        <enable_wind>0</enable_wind>
        <kinematic>0</kinematic>
      </link>
      <joint name='joint11' type='revolute'>
        <pose relative_to='l4_c'>0.04 0 0 0 -0.785 0</pose>
        <parent>l4_c</parent>
        <child>l4_f</child>
        <axis>
          <xyz>0 -1 0</xyz>
          <limit>
            <lower>-3.14</lower>
            <upper>3.14</upper>
            <effort>10</effort>
            <velocity>1</velocity>
          </limit>
          <dynamics>
            <damping>1.5</damping>
            <friction>0.1</friction>
            <spring_reference>0</spring_reference>
            <spring_stiffness>0</spring_stiffness>
          </dynamics>
        </axis>
      </joint>
      <link name='l4_f'>
        <pose relative_to='joint11'>0 0 0 0 -0 0</pose>
        <inertial>
          <pose>0 0 0 0 -0 0</pose>
          <mass>0.1</mass>
          <inertia>
            <ixx>0.01</ixx>
            <ixy>0</ixy>
            <ixz>0</ixz>
            <iyy>0.01</iyy>
            <iyz>0</iyz>
            <izz>0.01</izz>
          </inertia>
        </inertial>
        <collision name='l4_f_collision'>
          <pose>0.04 0 0 0 -0 0</pose>
          <geometry>
            <box>
              <size>0.08 0.02 0.02</size>
            </box>
          </geometry>
          <max_contacts>10</max_contacts>
          <surface>
            <contact>
              <ode/>
            </contact>
            <bounce/>
            <friction>
              <torsional>
                <ode/>
              </torsional>
              <ode/>
            </friction>
          </surface>
        </collision>
        <visual name='l4_f_visual'>
          <pose>0.04 0 0 0 -0 0</pose>
          <geometry>
            <box>
              <size>0.08 0.02 0.02</size>
            </box>
          </geometry>
        </visual>
        <self_collide>0</self_collide>
        <enable_wind>0</enable_wind>
        <kinematic>0</kinematic>
      </link>
      <joint name='joint12' type='revolute'>
        <pose relative_to='l4_f'>0.08 0 0 0 1.57 0</pose>
        <parent>l4_f</parent>
        <child>l4_t</child>
        <axis>
          <xyz>0 -1 0</xyz>
          <limit>
            <lower>-3.14</lower>
            <upper>3.14</upper>
            <effort>10</effort>
            <velocity>1</velocity>
          </limit>
          <dynamics>
            <damping>1.5</damping>
            <friction>0.1</friction>
            <spring_reference>0</spring_reference>
            <spring_stiffness>0</spring_stiffness>
          </dynamics>
        </axis>
      </joint>
      <link name='l4_t'>
        <pose relative_to='joint12'>0 0 0 0 -0 0</pose>
        <inertial>
          <pose>0 0 0 0 -0 0</pose>
          <mass>0.2</mass>
          <inertia>
            <ixx>0.001</ixx>
            <ixy>0</ixy>
            <ixz>0</ixz>
            <iyy>0.001</iyy>
            <iyz>0</iyz>
            <izz>0.001</izz>
          </inertia>
        </inertial>
        <collision name='l4_t_collision'>
          <pose>0.07 0 0 0 -0 0</pose>
          <geometry>
            <box>
              <size>0.14 0.04 0.04</size>
            </box>
          </geometry>
          <surface>
            <contact>
              <ode>
                <kp>10000</kp>
                <kd>10</kd>
              </ode>
            </contact>
            <friction>
              <ode>
                <mu>2</mu>
                <mu2>2</mu2>
              </ode>
              <torsional>
                <ode/>
              </torsional>
            </friction>
            <bounce/>
          </surface>
          <max_contacts>10</max_contacts>
        </collision>
        <visual name='l4_t_visual'>
          <pose>0.07 0 0 0 -0 0</pose>
          <geometry>
            <box>
              <size>0.1 0.04 0.04</size>
            </box>
          </geometry>
        </visual>
        <visual name='l4_t_visual_1'>
          <pose>0.02 0 0 1.5708 -0 0</pose>
          <geometry>
            <cylinder>
              <length>0.04</length>
              <radius>0.02</radius>
            </cylinder>
          </geometry>
        </visual>
        <visual name='l4_t_visual_2'>
          <pose>0.12 0 0 1.5708 -0 0</pose>
          <geometry>
            <cylinder>
              <length>0.04</length>
              <radius>0.02</radius>
            </cylinder>
          </geometry>
        </visual>
        <self_collide>0</self_collide>
        <enable_wind>0</enable_wind>
        <kinematic>0</kinematic>
      </link>
      <joint name='joint13' type='revolute'>
        <pose relative_to='base_link'>0 -0.12 0 0 0 -1.57</pose>
        <parent>base_link</parent>
        <child>l5_c</child>
        <axis>
          <xyz>0 0 1</xyz>
          <limit>
            <lower>-1.57</lower>
            <upper>1.57</upper>
            <effort>10</effort>
            <velocity>1</velocity>
          </limit>
          <dynamics>
            <damping>1.5</damping>
            <friction>0.1</friction>
            <spring_reference>0</spring_reference>
            <spring_stiffness>0</spring_stiffness>
          </dynamics>
        </axis>
      </joint>
      <link name='l5_c'>
        <pose relative_to='joint13'>0 0 0 0 -0 0</pose>
        <inertial>
          <pose>0 0 0 0 -0 0</pose>
          <mass>0.1</mass>
          <inertia>
            <ixx>0.01</ixx>
            <ixy>0</ixy>
            <ixz>0</ixz>
            <iyy>0.01</iyy>
            <iyz>0</iyz>
            <izz>0.01</izz>
          </inertia>
        </inertial>
        <collision name='l5_c_collision'>
          <pose>0.02 0 0 0 -0 0</pose>
          <geometry>
            <box>
              <size>0.04 0.02 0.02</size>
            </box>
          </geometry>
          <max_contacts>10</max_contacts>
          <surface>
            <contact>
              <ode/>
            </contact>
            <bounce/>
            <friction>
              <torsional>
                <ode/>
              </torsional>
              <ode/>
            </friction>
          </surface>
        </collision>
        <visual name='l5_c_visual'>
          <pose>0.02 0 0 0 -0 0</pose>
          <geometry>
            <box>
              <size>0.04 0.02 0.02</size>
            </box>
          </geometry>
        </visual>
        <self_collide>0</self_collide>
        <enable_wind>0</enable_wind>
        <kinematic>0</kinematic>
      </link>
      <joint name='joint14' type='revolute'>
        <pose relative_to='l5_c'>0.04 0 0 0 -0.785 0</pose>
        <parent>l5_c</parent>
        <child>l5_f</child>
        <axis>
          <xyz>0 -1 0</xyz>
          <limit>
            <lower>-3.14</lower>
            <upper>3.14</upper>
            <effort>10</effort>
            <velocity>1</velocity>
          </limit>
          <dynamics>
            <damping>1.5</damping>
            <friction>0.1</friction>
            <spring_reference>0</spring_reference>
            <spring_stiffness>0</spring_stiffness>
          </dynamics>
        </axis>
      </joint>
      <link name='l5_f'>
        <pose relative_to='joint14'>0 0 0 0 -0 0</pose>
        <inertial>
          <pose>0 0 0 0 -0 0</pose>
          <mass>0.1</mass>
          <inertia>
            <ixx>0.01</ixx>
            <ixy>0</ixy>
            <ixz>0</ixz>
            <iyy>0.01</iyy>
            <iyz>0</iyz>
            <izz>0.01</izz>
          </inertia>
        </inertial>
        <collision name='l5_f_collision'>
          <pose>0.04 0 0 0 -0 0</pose>
          <geometry>
            <box>
              <size>0.08 0.02 0.02</size>
            </box>
          </geometry>
          <max_contacts>10</max_contacts>
          <surface>
            <contact>
              <ode/>
            </contact>
            <bounce/>
            <friction>
              <torsional>
                <ode/>
              </torsional>
              <ode/>
            </friction>
          </surface>
        </collision>
        <visual name='l5_f_visual'>
          <pose>0.04 0 0 0 -0 0</pose>
          <geometry>
            <box>
              <size>0.08 0.02 0.02</size>
            </box>
          </geometry>
        </visual>
        <self_collide>0</self_collide>
        <enable_wind>0</enable_wind>
        <kinematic>0</kinematic>
      </link>
      <joint name='joint15' type='revolute'>
        <pose relative_to='l5_f'>0.08 0 0 0 1.57 0</pose>
        <parent>l5_f</parent>
        <child>l5_t</child>
        <axis>
          <xyz>0 -1 0</xyz>
          <limit>
            <lower>-3.14</lower>
            <upper>3.14</upper>
            <effort>10</effort>
            <velocity>1</velocity>
          </limit>
          <dynamics>
            <damping>1.5</damping>
            <friction>0.1</friction>
            <spring_reference>0</spring_reference>
            <spring_stiffness>0</spring_stiffness>
          </dynamics>
        </axis>
      </joint>
      <link name='l5_t'>
        <pose relative_to='joint15'>0 0 0 0 -0 0</pose>
        <inertial>
          <pose>0 0 0 0 -0 0</pose>
          <mass>0.1</mass>
          <inertia>
            <ixx>0.01</ixx>
            <ixy>0</ixy>
            <ixz>0</ixz>
            <iyy>0.01</iyy>
            <iyz>0</iyz>
            <izz>0.01</izz>
          </inertia>
        </inertial>
        <collision name='l5_t_collision'>
          <pose>0.07 0 0 0 -0 0</pose>
          <geometry>
            <box>
              <size>0.14 0.02 0.02</size>
            </box>
          </geometry>
          <surface>
            <contact>
              <ode>
                <kp>10000</kp>
                <kd>10</kd>
              </ode>
            </contact>
            <friction>
              <ode>
                <mu>2</mu>
                <mu2>2</mu2>
              </ode>
              <torsional>
                <ode/>
              </torsional>
            </friction>
            <bounce/>
          </surface>
          <max_contacts>10</max_contacts>
        </collision>
        <visual name='l5_t_visual'>
          <pose>0.07 0 0 0 -0 0</pose>
          <geometry>
            <box>
              <size>0.14 0.02 0.02</size>
            </box>
          </geometry>
        </visual>
        <self_collide>0</self_collide>
        <enable_wind>0</enable_wind>
        <kinematic>0</kinematic>
      </link>
      <joint name='joint16' type='revolute'>
        <pose relative_to='base_link'>0.1 -0.1 0 0 0 -0.785</pose>
        <parent>base_link</parent>
        <child>l6_c</child>
        <axis>
          <xyz>0 0 1</xyz>
          <limit>
            <lower>-1.57</lower>
            <upper>1.57</upper>
            <effort>10</effort>
            <velocity>1</velocity>
          </limit>
          <dynamics>
            <damping>1.5</damping>
            <friction>0.1</friction>
            <spring_reference>0</spring_reference>
            <spring_stiffness>0</spring_stiffness>
          </dynamics>
        </axis>
      </joint>
      <link name='l6_c'>
        <pose relative_to='joint16'>0 0 0 0 -0 0</pose>
        <inertial>
          <pose>0 0 0 0 -0 0</pose>
          <mass>0.1</mass>
          <inertia>
            <ixx>0.01</ixx>
            <ixy>0</ixy>
            <ixz>0</ixz>
            <iyy>0.01</iyy>
            <iyz>0</iyz>
            <izz>0.01</izz>
          </inertia>
        </inertial>
        <collision name='l6_c_collision'>
          <pose>0.02 0 0 0 -0 0</pose>
          <geometry>
            <box>
              <size>0.04 0.02 0.02</size>
            </box>
          </geometry>
          <max_contacts>10</max_contacts>
          <surface>
            <contact>
              <ode/>
            </contact>
            <bounce/>
            <friction>
              <torsional>
                <ode/>
              </torsional>
              <ode/>
            </friction>
          </surface>
        </collision>
        <visual name='l6_c_visual'>
          <pose>0.02 0 0 0 -0 0</pose>
          <geometry>
            <box>
              <size>0.04 0.02 0.02</size>
            </box>
          </geometry>
        </visual>
        <self_collide>0</self_collide>
        <enable_wind>0</enable_wind>
        <kinematic>0</kinematic>
      </link>
      <joint name='joint17' type='revolute'>
        <pose relative_to='l6_c'>0.04 0 0 0 -0.785 0</pose>
        <parent>l6_c</parent>
        <child>l6_f</child>
        <axis>
          <xyz>0 -1 0</xyz>
          <limit>
            <lower>-3.14</lower>
            <upper>3.14</upper>
            <effort>10</effort>
            <velocity>1</velocity>
          </limit>
          <dynamics>
            <damping>1.5</damping>
            <friction>0.1</friction>
            <spring_reference>0</spring_reference>
            <spring_stiffness>0</spring_stiffness>
          </dynamics>
        </axis>
      </joint>
      <link name='l6_f'>
        <pose relative_to='joint17'>0 0 0 0 -0 0</pose>
        <inertial>
          <pose>0 0 0 0 -0 0</pose>
          <mass>0.1</mass>
          <inertia>
            <ixx>0.01</ixx>
            <ixy>0</ixy>
            <ixz>0</ixz>
            <iyy>0.01</iyy>
            <iyz>0</iyz>
            <izz>0.01</izz>
          </inertia>
        </inertial>
        <collision name='l6_f_collision'>
          <pose>0.04 0 0 0 -0 0</pose>
          <geometry>
            <box>
              <size>0.08 0.02 0.02</size>
            </box>
          </geometry>
          <max_contacts>10</max_contacts>
          <surface>
            <contact>
              <ode/>
            </contact>
            <bounce/>
            <friction>
              <torsional>
                <ode/>
              </torsional>
              <ode/>
            </friction>
          </surface>
        </collision>
        <visual name='l6_f_visual'>
          <pose>0.04 0 0 0 -0 0</pose>
          <geometry>
            <box>
              <size>0.08 0.02 0.02</size>
            </box>
          </geometry>
        </visual>
        <self_collide>0</self_collide>
        <enable_wind>0</enable_wind>
        <kinematic>0</kinematic>
      </link>
      <joint name='joint18' type='revolute'>
        <pose relative_to='l6_f'>0.08 0 0 0 1.57 0</pose>
        <parent>l6_f</parent>
        <child>l6_t</child>
        <axis>
          <xyz>0 -1 0</xyz>
          <limit>
            <lower>-3.14</lower>
            <upper>3.14</upper>
            <effort>10</effort>
            <velocity>1</velocity>
          </limit>
          <dynamics>
            <damping>1.5</damping>
            <friction>0.1</friction>
            <spring_reference>0</spring_reference>
            <spring_stiffness>0</spring_stiffness>
          </dynamics>
        </axis>
      </joint>
      <link name='l6_t'>
        <pose relative_to='joint18'>0 0 0 0 -0 0</pose>
        <inertial>
          <pose>0 0 0 0 -0 0</pose>
          <mass>0.2</mass>
          <inertia>
            <ixx>0.001</ixx>
            <ixy>0</ixy>
            <ixz>0</ixz>
            <iyy>0.001</iyy>
            <iyz>0</iyz>
            <izz>0.001</izz>
          </inertia>
        </inertial>
        <collision name='l6_t_collision'>
          <pose>0.07 0 0 0 -0 0</pose>
          <geometry>
            <box>
              <size>0.14 0.04 0.04</size>
            </box>
          </geometry>
          <surface>
            <contact>
              <ode>
                <kp>10000</kp>
                <kd>10</kd>
              </ode>
            </contact>
            <friction>
              <ode>
                <mu>2</mu>
                <mu2>2</mu2>
              </ode>
              <torsional>
                <ode/>
              </torsional>
            </friction>
            <bounce/>
          </surface>
          <max_contacts>10</max_contacts>
        </collision>
        <visual name='l6_t_visual'>
          <pose>0.07 0 0 0 -0 0</pose>
          <geometry>
            <box>
              <size>0.1 0.04 0.04</size>
            </box>
          </geometry>
        </visual>
        <visual name='l6_t_visual_1'>
          <pose>0.02 0 0 1.5708 -0 0</pose>
          <geometry>
            <cylinder>
              <length>0.04</length>
              <radius>0.02</radius>
            </cylinder>
          </geometry>
        </visual>
        <visual name='l6_t_visual_2'>
          <pose>0.12 0 0 1.5708 -0 0</pose>
          <geometry>
            <cylinder>
              <length>0.04</length>
              <radius>0.02</radius>
            </cylinder>
          </geometry>
        </visual>
        <self_collide>0</self_collide>
        <enable_wind>0</enable_wind>
        <kinematic>0</kinematic>
      </link>
      <joint name='joint4' type='revolute'>
        <pose relative_to='base_link'>0 0.12 0 0 -0 1.57</pose>
        <parent>base_link</parent>
        <child>l2_c</child>
        <axis>
          <xyz>0 0 1</xyz>
          <limit>
            <lower>-1.57</lower>
            <upper>1.57</upper>
            <effort>10</effort>
            <velocity>1</velocity>
          </limit>
          <dynamics>
            <damping>1.5</damping>
            <friction>0.1</friction>
            <spring_reference>0</spring_reference>
            <spring_stiffness>0</spring_stiffness>
          </dynamics>
        </axis>
      </joint>
      <link name='l2_c'>
        <pose relative_to='joint4'>0 0 0 0 -0 0</pose>
        <inertial>
          <pose>0 0 0 0 -0 0</pose>
          <mass>0.1</mass>
          <inertia>
            <ixx>0.01</ixx>
            <ixy>0</ixy>
            <ixz>0</ixz>
            <iyy>0.01</iyy>
            <iyz>0</iyz>
            <izz>0.01</izz>
          </inertia>
        </inertial>
        <collision name='l2_c_collision'>
          <pose>0.02 0 0 0 -0 0</pose>
          <geometry>
            <box>
              <size>0.04 0.02 0.02</size>
            </box>
          </geometry>
          <max_contacts>10</max_contacts>
          <surface>
            <contact>
              <ode/>
            </contact>
            <bounce/>
            <friction>
              <torsional>
                <ode/>
              </torsional>
              <ode/>
            </friction>
          </surface>
        </collision>
        <visual name='l2_c_visual'>
          <pose>0.02 0 0 0 -0 0</pose>
          <geometry>
            <box>
              <size>0.04 0.02 0.02</size>
            </box>
          </geometry>
        </visual>
        <self_collide>0</self_collide>
        <enable_wind>0</enable_wind>
        <kinematic>0</kinematic>
      </link>
      <joint name='joint5' type='revolute'>
        <pose relative_to='l2_c'>0.04 0 0 0 -0.785 0</pose>
        <parent>l2_c</parent>
        <child>l2_f</child>
        <axis>
          <xyz>0 -1 0</xyz>
          <limit>
            <lower>-3.14</lower>
            <upper>3.14</upper>
            <effort>10</effort>
            <velocity>1</velocity>
          </limit>
          <dynamics>
            <damping>1.5</damping>
            <friction>0.1</friction>
            <spring_reference>0</spring_reference>
            <spring_stiffness>0</spring_stiffness>
          </dynamics>
        </axis>
      </joint>
      <link name='l2_f'>
        <pose relative_to='joint5'>0 0 0 0 -0 0</pose>
        <inertial>
          <pose>0 0 0 0 -0 0</pose>
          <mass>0.1</mass>
          <inertia>
            <ixx>0.01</ixx>
            <ixy>0</ixy>
            <ixz>0</ixz>
            <iyy>0.01</iyy>
            <iyz>0</iyz>
            <izz>0.01</izz>
          </inertia>
        </inertial>
        <collision name='l2_f_collision'>
          <pose>0.04 0 0 0 -0 0</pose>
          <geometry>
            <box>
              <size>0.08 0.02 0.02</size>
            </box>
          </geometry>
          <max_contacts>10</max_contacts>
          <surface>
            <contact>
              <ode/>
            </contact>
            <bounce/>
            <friction>
              <torsional>
                <ode/>
              </torsional>
              <ode/>
            </friction>
          </surface>
        </collision>
        <visual name='l2_f_visual'>
          <pose>0.04 0 0 0 -0 0</pose>
          <geometry>
            <box>
              <size>0.08 0.02 0.02</size>
            </box>
          </geometry>
        </visual>
        <self_collide>0</self_collide>
        <enable_wind>0</enable_wind>
        <kinematic>0</kinematic>
      </link>
      <joint name='joint6' type='revolute'>
        <pose relative_to='l2_f'>0.08 0 0 0 1.57 0</pose>
        <parent>l2_f</parent>
        <child>l2_t</child>
        <axis>
          <xyz>0 -1 0</xyz>
          <limit>
            <lower>-3.14</lower>
            <upper>3.14</upper>
            <effort>10</effort>
            <velocity>1</velocity>
          </limit>
          <dynamics>
            <damping>1.5</damping>
            <friction>0.1</friction>
            <spring_reference>0</spring_reference>
            <spring_stiffness>0</spring_stiffness>
          </dynamics>
        </axis>
      </joint>
      <link name='l2_t'>
        <pose relative_to='joint6'>0 0 0 0 -0 0</pose>
        <inertial>
          <pose>0 0 0 0 -0 0</pose>
          <mass>0.1</mass>
          <inertia>
            <ixx>0.01</ixx>
            <ixy>0</ixy>
            <ixz>0</ixz>
            <iyy>0.01</iyy>
            <iyz>0</iyz>
            <izz>0.01</izz>
          </inertia>
        </inertial>
        <collision name='l2_t_collision'>
          <pose>0.07 0 0 0 -0 0</pose>
          <geometry>
            <box>
              <size>0.14 0.02 0.02</size>
            </box>
          </geometry>
          <surface>
            <contact>
              <ode>
                <kp>10000</kp>
                <kd>10</kd>
              </ode>
            </contact>
            <friction>
              <ode>
                <mu>2</mu>
                <mu2>2</mu2>
              </ode>
              <torsional>
                <ode/>
              </torsional>
            </friction>
            <bounce/>
          </surface>
          <max_contacts>10</max_contacts>
        </collision>
        <visual name='l2_t_visual'>
          <pose>0.07 0 0 0 -0 0</pose>
          <geometry>
            <box>
              <size>0.14 0.02 0.02</size>
            </box>
          </geometry>
        </visual>
        <self_collide>0</self_collide>
        <enable_wind>0</enable_wind>
        <kinematic>0</kinematic>
      </link>
      <joint name='joint7' type='revolute'>
        <pose relative_to='base_link'>-0.1 0.1 0 0 -0 2.355</pose>
        <parent>base_link</parent>
        <child>l3_c</child>
        <axis>
          <xyz>0 0 1</xyz>
          <limit>
            <lower>-1.57</lower>
            <upper>1.57</upper>
            <effort>10</effort>
            <velocity>1</velocity>
          </limit>
          <dynamics>
            <damping>1.5</damping>
            <friction>0.1</friction>
            <spring_reference>0</spring_reference>
            <spring_stiffness>0</spring_stiffness>
          </dynamics>
        </axis>
      </joint>
      <link name='l3_c'>
        <pose relative_to='joint7'>0 0 0 0 -0 0</pose>
        <inertial>
          <pose>0 0 0 0 -0 0</pose>
          <mass>0.1</mass>
          <inertia>
            <ixx>0.01</ixx>
            <ixy>0</ixy>
            <ixz>0</ixz>
            <iyy>0.01</iyy>
            <iyz>0</iyz>
            <izz>0.01</izz>
          </inertia>
        </inertial>
        <collision name='l3_c_collision'>
          <pose>0.02 0 0 0 -0 0</pose>
          <geometry>
            <box>
              <size>0.04 0.02 0.02</size>
            </box>
          </geometry>
          <max_contacts>10</max_contacts>
          <surface>
            <contact>
              <ode/>
            </contact>
            <bounce/>
            <friction>
              <torsional>
                <ode/>
              </torsional>
              <ode/>
            </friction>
          </surface>
        </collision>
        <visual name='l3_c_visual'>
          <pose>0.02 0 0 0 -0 0</pose>
          <geometry>
            <box>
              <size>0.04 0.02 0.02</size>
            </box>
          </geometry>
        </visual>
        <self_collide>0</self_collide>
        <enable_wind>0</enable_wind>
        <kinematic>0</kinematic>
      </link>
      <joint name='joint8' type='revolute'>
        <pose relative_to='l3_c'>0.04 0 0 0 -0.785 0</pose>
        <parent>l3_c</parent>
        <child>l3_f</child>
        <axis>
          <xyz>0 -1 0</xyz>
          <limit>
            <lower>-3.14</lower>
            <upper>3.14</upper>
            <effort>10</effort>
            <velocity>1</velocity>
          </limit>
          <dynamics>
            <damping>1.5</damping>
            <friction>0.1</friction>
            <spring_reference>0</spring_reference>
            <spring_stiffness>0</spring_stiffness>
          </dynamics>
        </axis>
      </joint>
      <link name='l3_f'>
        <pose relative_to='joint8'>0 0 0 0 -0 0</pose>
        <inertial>
          <pose>0 0 0 0 -0 0</pose>
          <mass>0.1</mass>
          <inertia>
            <ixx>0.01</ixx>
            <ixy>0</ixy>
            <ixz>0</ixz>
            <iyy>0.01</iyy>
            <iyz>0</iyz>
            <izz>0.01</izz>
          </inertia>
        </inertial>
        <collision name='l3_f_collision'>
          <pose>0.04 0 0 0 -0 0</pose>
          <geometry>
            <box>
              <size>0.08 0.02 0.02</size>
            </box>
          </geometry>
          <max_contacts>10</max_contacts>
          <surface>
            <contact>
              <ode/>
            </contact>
            <bounce/>
            <friction>
              <torsional>
                <ode/>
              </torsional>
              <ode/>
            </friction>
          </surface>
        </collision>
        <visual name='l3_f_visual'>
          <pose>0.04 0 0 0 -0 0</pose>
          <geometry>
            <box>
              <size>0.08 0.02 0.02</size>
            </box>
          </geometry>
        </visual>
        <self_collide>0</self_collide>
        <enable_wind>0</enable_wind>
        <kinematic>0</kinematic>
      </link>
      <joint name='joint9' type='revolute'>
        <pose relative_to='l3_f'>0.08 0 0 0 1.57 0</pose>
        <parent>l3_f</parent>
        <child>l3_t</child>
        <axis>
          <xyz>0 -1 0</xyz>
          <limit>
            <lower>-3.14</lower>
            <upper>3.14</upper>
            <effort>10</effort>
            <velocity>1</velocity>
          </limit>
          <dynamics>
            <damping>1.5</damping>
            <friction>0.1</friction>
            <spring_reference>0</spring_reference>
            <spring_stiffness>0</spring_stiffness>
          </dynamics>
        </axis>
      </joint>
      <link name='l3_t'>
        <pose relative_to='joint9'>0 0 0 0 -0 0</pose>
        <inertial>
          <pose>0 0 0 0 -0 0</pose>
          <mass>0.2</mass>
          <inertia>
            <ixx>0.001</ixx>
            <ixy>0</ixy>
            <ixz>0</ixz>
            <iyy>0.001</iyy>
            <iyz>0</iyz>
            <izz>0.001</izz>
          </inertia>
        </inertial>
        <collision name='l3_t_collision'>
          <pose>0.07 0 0 0 -0 0</pose>
          <geometry>
            <box>
              <size>0.14 0.04 0.04</size>
            </box>
          </geometry>
          <surface>
            <contact>
              <ode>
                <kp>10000</kp>
                <kd>10</kd>
              </ode>
            </contact>
            <friction>
              <ode>
                <mu>2</mu>
                <mu2>2</mu2>
              </ode>
              <torsional>
                <ode/>
              </torsional>
            </friction>
            <bounce/>
          </surface>
          <max_contacts>10</max_contacts>
        </collision>
        <visual name='l3_t_visual'>
          <pose>0.07 0 0 0 -0 0</pose>
          <geometry>
            <box>
              <size>0.1 0.04 0.04</size>
            </box>
          </geometry>
        </visual>
        <visual name='l3_t_visual_1'>
          <pose>0.02 0 0 1.5708 -0 0</pose>
          <geometry>
            <cylinder>
              <length>0.04</length>
              <radius>0.02</radius>
            </cylinder>
          </geometry>
        </visual>
        <visual name='l3_t_visual_2'>
          <pose>0.12 0 0 1.5708 -0 0</pose>
          <geometry>
            <cylinder>
              <length>0.04</length>
              <radius>0.02</radius>
            </cylinder>
          </geometry>
        </visual>
        <self_collide>0</self_collide>
        <enable_wind>0</enable_wind>
        <kinematic>0</kinematic>
      </link>
      <static>0</static>
      <plugin name='gazebo_ros2_control' filename='libgazebo_ros2_control.so'>
        <parameters>/home/chia/spider_ws/install/spider_bot/share/spider_bot/config/spider_bot_controllers.yaml</parameters>
      </plugin>
      <plugin name='gazebo_ros_p3d' filename='libgazebo_ros_p3d.so'>
        <ros>
          <namespace>/</namespace>
          <remapping>odom:=odom</remapping>
        </ros>
        <body_name>base_link</body_name>
        <frame_name>world</frame_name>
        <update_rate>50</update_rate>
      </plugin>
      <pose>0 0 1.2 0 -0 0</pose>
    </model>
    <model name='terrain_block_0_0'>
      <static>1</static>
      <link name='link'>
        <collision name='collision'>
          <geometry>
            <box>
              <size>0.19 0.19 0.030729</size>
            </box>
          </geometry>
          <max_contacts>10</max_contacts>
          <surface>
            <contact>
              <ode/>
            </contact>
            <bounce/>
            <friction>
              <torsional>
                <ode/>
              </torsional>
              <ode/>
            </friction>
          </surface>
        </collision>
        <visual name='visual'>
          <geometry>
            <box>
              <size>0.19 0.19 0.030729</size>
            </box>
          </geometry>
          <material>
            <ambient>0.5 0.3 0.1 1</ambient>
          </material>
        </visual>
        <self_collide>0</self_collide>
        <enable_wind>0</enable_wind>
        <kinematic>0</kinematic>
      </link>
      <pose>-0.8 -0.8 0.015365 0 -0 0</pose>
    </model>
    <model name='terrain_block_0_1'>
      <static>1</static>
      <link name='link'>
        <collision name='collision'>
          <geometry>
            <box>
              <size>0.19 0.19 0.027995</size>
            </box>
          </geometry>
          <max_contacts>10</max_contacts>
          <surface>
            <contact>
              <ode/>
            </contact>
            <bounce/>
            <friction>
              <torsional>
                <ode/>
              </torsional>
              <ode/>
            </friction>
          </surface>
        </collision>
        <visual name='visual'>
          <geometry>
            <box>
              <size>0.19 0.19 0.027995</size>
            </box>
          </geometry>
          <material>
            <ambient>0.5 0.3 0.1 1</ambient>
          </material>
        </visual>
        <self_collide>0</self_collide>
        <enable_wind>0</enable_wind>
        <kinematic>0</kinematic>
      </link>
      <pose>-0.8 -0.6 0.013998 0 -0 0</pose>
    </model>
    <model name='terrain_block_0_2'>
      <static>1</static>
      <link name='link'>
        <collision name='collision'>
          <geometry>
            <box>
              <size>0.19 0.19 0.057687</size>
            </box>
          </geometry>
          <max_contacts>10</max_contacts>
          <surface>
            <contact>
              <ode/>
            </contact>
            <bounce/>
            <friction>
              <torsional>
                <ode/>
              </torsional>
              <ode/>
            </friction>
          </surface>
        </collision>
        <visual name='visual'>
          <geometry>
            <box>
              <size>0.19 0.19 0.057687</size>
            </box>
          </geometry>
          <material>
            <ambient>0.5 0.3 0.1 1</ambient>
          </material>
        </visual>
        <self_collide>0</self_collide>
        <enable_wind>0</enable_wind>
        <kinematic>0</kinematic>
      </link>
      <pose>-0.8 -0.4 0.028844 0 -0 0</pose>
    </model>
    <model name='terrain_block_0_3'>
      <static>1</static>
      <link name='link'>
        <collision name='collision'>
          <geometry>
            <box>
              <size>0.19 0.19 0.043119</size>
            </box>
          </geometry>
          <max_contacts>10</max_contacts>
          <surface>
            <contact>
              <ode/>
            </contact>
            <bounce/>
            <friction>
              <torsional>
                <ode/>
              </torsional>
              <ode/>
            </friction>
          </surface>
        </collision>
        <visual name='visual'>
          <geometry>
            <box>
              <size>0.19 0.19 0.043119</size>
            </box>
          </geometry>
          <material>
            <ambient>0.5 0.3 0.1 1</ambient>
          </material>
        </visual>
        <self_collide>0</self_collide>
        <enable_wind>0</enable_wind>
        <kinematic>0</kinematic>
      </link>
      <pose>-0.8 -0.2 0.021559 0 -0 0</pose>
    </model>
    <model name='terrain_block_0_4'>
      <static>1</static>
      <link name='link'>
        <collision name='collision'>
          <geometry>
            <box>
              <size>0.19 0.19 0.066355</size>
            </box>
          </geometry>
          <max_contacts>10</max_contacts>
          <surface>
            <contact>
              <ode/>
            </contact>
            <bounce/>
            <friction>
              <torsional>
                <ode/>
              </torsional>
              <ode/>
            </friction>
          </surface>
        </collision>
        <visual name='visual'>
          <geometry>
            <box>
              <size>0.19 0.19 0.066355</size>
            </box>
          </geometry>
          <material>
            <ambient>0.5 0.3 0.1 1</ambient>
          </material>
        </visual>
        <self_collide>0</self_collide>
        <enable_wind>0</enable_wind>
        <kinematic>0</kinematic>
      </link>
      <pose>-0.8 0 0.033177 0 -0 0</pose>
    </model>
    <model name='terrain_block_0_5'>
      <static>1</static>
      <link name='link'>
        <collision name='collision'>
          <geometry>
            <box>
              <size>0.19 0.19 0.067092</size>
            </box>
          </geometry>
          <max_contacts>10</max_contacts>
          <surface>
            <contact>
              <ode/>
            </contact>
            <bounce/>
            <friction>
              <torsional>
                <ode/>
              </torsional>
              <ode/>
            </friction>
          </surface>
        </collision>
        <visual name='visual'>
          <geometry>
            <box>
              <size>0.19 0.19 0.067092</size>
            </box>
          </geometry>
          <material>
            <ambient>0.5 0.3 0.1 1</ambient>
          </material>
        </visual>
        <self_collide>0</self_collide>
        <enable_wind>0</enable_wind>
        <kinematic>0</kinematic>
      </link>
      <pose>-0.8 0.2 0.033546 0 -0 0</pose>
    </model>
    <model name='terrain_block_0_6'>
      <static>1</static>
      <link name='link'>
        <collision name='collision'>
          <geometry>
            <box>
              <size>0.19 0.19 0.06284</size>
            </box>
          </geometry>
          <max_contacts>10</max_contacts>
          <surface>
            <contact>
              <ode/>
            </contact>
            <bounce/>
            <friction>
              <torsional>
                <ode/>
              </torsional>
              <ode/>
            </friction>
          </surface>
        </collision>
        <visual name='visual'>
          <geometry>
            <box>
              <size>0.19 0.19 0.06284</size>
            </box>
          </geometry>
          <material>
            <ambient>0.5 0.3 0.1 1</ambient>
          </material>
        </visual>
        <self_collide>0</self_collide>
        <enable_wind>0</enable_wind>
        <kinematic>0</kinematic>
      </link>
      <pose>-0.8 0.4 0.03142 0 -0 0</pose>
    </model>
    <model name='terrain_block_0_7'>
      <static>1</static>
      <link name='link'>
        <collision name='collision'>
          <geometry>
            <box>
              <size>0.19 0.19 0.025576</size>
            </box>
          </geometry>
          <max_contacts>10</max_contacts>
          <surface>
            <contact>
              <ode/>
            </contact>
            <bounce/>
            <friction>
              <torsional>
                <ode/>
              </torsional>
              <ode/>
            </friction>
          </surface>
        </collision>
        <visual name='visual'>
          <geometry>
            <box>
              <size>0.19 0.19 0.025576</size>
            </box>
          </geometry>
          <material>
            <ambient>0.5 0.3 0.1 1</ambient>
          </material>
        </visual>
        <self_collide>0</self_collide>
        <enable_wind>0</enable_wind>
        <kinematic>0</kinematic>
      </link>
      <pose>-0.8 0.6 0.012788 0 -0 0</pose>
    </model>
    <model name='terrain_block_1_0'>
      <static>1</static>
      <link name='link'>
        <collision name='collision'>
          <geometry>
            <box>
              <size>0.19 0.19 0.025223</size>
            </box>
          </geometry>
          <max_contacts>10</max_contacts>
          <surface>
            <contact>
              <ode/>
            </contact>
            <bounce/>
            <friction>
              <torsional>
                <ode/>
              </torsional>
              <ode/>
            </friction>
          </surface>
        </collision>
        <visual name='visual'>
          <geometry>
            <box>
              <size>0.19 0.19 0.025223</size>
            </box>
          </geometry>
          <material>
            <ambient>0.5 0.3 0.1 1</ambient>
          </material>
        </visual>
        <self_collide>0</self_collide>
        <enable_wind>0</enable_wind>
        <kinematic>0</kinematic>
      </link>
      <pose>-0.6 -0.8 0.012611 0 -0 0</pose>
    </model>
    <model name='terrain_block_1_1'>
      <static>1</static>
      <link name='link'>
        <collision name='collision'>
          <geometry>
            <box>
              <size>0.19 0.19 0.052018</size>
            </box>
          </geometry>
          <max_contacts>10</max_contacts>
          <surface>
            <contact>
              <ode/>
            </contact>
            <bounce/>
            <friction>
              <torsional>
                <ode/>
              </torsional>
              <ode/>
            </friction>
          </surface>
        </collision>
        <visual name='visual'>
          <geometry>
            <box>
              <size>0.19 0.19 0.052018</size>
            </box>
          </geometry>
          <material>
            <ambient>0.5 0.3 0.1 1</ambient>
          </material>
        </visual>
        <self_collide>0</self_collide>
        <enable_wind>0</enable_wind>
        <kinematic>0</kinematic>
      </link>
      <pose>-0.6 -0.6 0.026009 0 -0 0</pose>
    </model>
    <model name='terrain_block_1_2'>
      <static>1</static>
      <link name='link'>
        <collision name='collision'>
          <geometry>
            <box>
              <size>0.19 0.19 0.047937</size>
            </box>
          </geometry>
          <max_contacts>10</max_contacts>
          <surface>
            <contact>
              <ode/>
            </contact>
            <bounce/>
            <friction>
              <torsional>
                <ode/>
              </torsional>
              <ode/>
            </friction>
          </surface>
        </collision>
        <visual name='visual'>
          <geometry>
            <box>
              <size>0.19 0.19 0.047937</size>
            </box>
          </geometry>
          <material>
            <ambient>0.5 0.3 0.1 1</ambient>
          </material>
        </visual>
        <self_collide>0</self_collide>
        <enable_wind>0</enable_wind>
        <kinematic>0</kinematic>
      </link>
      <pose>-0.6 -0.4 0.023969 0 -0 0</pose>
    </model>
    <model name='terrain_block_1_3'>
      <static>1</static>
      <link name='link'>
        <collision name='collision'>
          <geometry>
            <box>
              <size>0.19 0.19 0.029502</size>
            </box>
          </geometry>
          <max_contacts>10</max_contacts>
          <surface>
            <contact>
              <ode/>
            </contact>
            <bounce/>
            <friction>
              <torsional>
                <ode/>
              </torsional>
              <ode/>
            </friction>
          </surface>
        </collision>
        <visual name='visual'>
          <geometry>
            <box>
              <size>0.19 0.19 0.029502</size>
            </box>
          </geometry>
          <material>
            <ambient>0.5 0.3 0.1 1</ambient>
          </material>
        </visual>
        <self_collide>0</self_collide>
        <enable_wind>0</enable_wind>
        <kinematic>0</kinematic>
      </link>
      <pose>-0.6 -0.2 0.014751 0 -0 0</pose>
    </model>
    <model name='terrain_block_1_4'>
      <static>1</static>
      <link name='link'>
        <collision name='collision'>
          <geometry>
            <box>
              <size>0.19 0.19 0.05982</size>
            </box>
          </geometry>
          <max_contacts>10</max_contacts>
          <surface>
            <contact>
              <ode/>
            </contact>
            <bounce/>
            <friction>
              <torsional>
                <ode/>
              </torsional>
              <ode/>
            </friction>
          </surface>
        </collision>
        <visual name='visual'>
          <geometry>
            <box>
              <size>0.19 0.19 0.05982</size>
            </box>
          </geometry>
          <material>
            <ambient>0.5 0.3 0.1 1</ambient>
          </material>
        </visual>
        <self_collide>0</self_collide>
        <enable_wind>0</enable_wind>
        <kinematic>0</kinematic>
      </link>
      <pose>-0.6 0 0.02991 0 -0 0</pose>
    </model>
    <model name='terrain_block_1_5'>
      <static>1</static>
      <link name='link'>
        <collision name='collision'>
          <geometry>
            <box>
              <size>0.19 0.19 0.041989</size>
            </box>
          </geometry>
          <max_contacts>10</max_contacts>
          <surface>
            <contact>
              <ode/>
            </contact>
            <bounce/>
            <friction>
              <torsional>
                <ode/>
              </torsional>
              <ode/>
            </friction>
          </surface>
        </collision>
        <visual name='visual'>
          <geometry>
            <box>
              <size>0.19 0.19 0.041989</size>
            </box>
          </geometry>
          <material>
            <ambient>0.5 0.3 0.1 1</ambient>
          </material>
        </visual>
        <self_collide>0</self_collide>
        <enable_wind>0</enable_wind>
        <kinematic>0</kinematic>
      </link>
      <pose>-0.6 0.2 0.020995 0 -0 0</pose>
    </model>
    <model name='terrain_block_1_6'>
      <static>1</static>
      <link name='link'>
        <collision name='collision'>
          <geometry>
            <box>
              <size>0.19 0.19 0.052518</size>
            </box>
          </geometry>
          <max_contacts>10</max_contacts>
          <surface>
            <contact>
              <ode/>
            </contact>
            <bounce/>
            <friction>
              <torsional>
                <ode/>
              </torsional>
              <ode/>
            </friction>
          </surface>
        </collision>
        <visual name='visual'>
          <geometry>
            <box>
              <size>0.19 0.19 0.052518</size>
            </box>
          </geometry>
          <material>
            <ambient>0.5 0.3 0.1 1</ambient>
          </material>
        </visual>
        <self_collide>0</self_collide>
        <enable_wind>0</enable_wind>
        <kinematic>0</kinematic>
      </link>
      <pose>-0.6 0.4 0.026259 0 -0 0</pose>
    </model>
    <model name='terrain_block_1_7'>
      <static>1</static>
      <link name='link'>
        <collision name='collision'>
          <geometry>
            <box>
              <size>0.19 0.19 0.022545</size>
            </box>
          </geometry>
          <max_contacts>10</max_contacts>
          <surface>
            <contact>
              <ode/>
            </contact>
            <bounce/>
            <friction>
              <torsional>
                <ode/>
              </torsional>
              <ode/>
            </friction>
          </surface>
        </collision>
        <visual name='visual'>
          <geometry>
            <box>
              <size>0.19 0.19 0.022545</size>
            </box>
          </geometry>
          <material>
            <ambient>0.5 0.3 0.1 1</ambient>
          </material>
        </visual>
        <self_collide>0</self_collide>
        <enable_wind>0</enable_wind>
        <kinematic>0</kinematic>
      </link>
      <pose>-0.6 0.6 0.011272 0 -0 0</pose>
    </model>
    <model name='terrain_block_2_0'>
      <static>1</static>
      <link name='link'>
        <collision name='collision'>
          <geometry>
            <box>
              <size>0.19 0.19 0.020032</size>
            </box>
          </geometry>
          <max_contacts>10</max_contacts>
          <surface>
            <contact>
              <ode/>
            </contact>
            <bounce/>
            <friction>
              <torsional>
                <ode/>
              </torsional>
              <ode/>
            </friction>
          </surface>
        </collision>
        <visual name='visual'>
          <geometry>
            <box>
              <size>0.19 0.19 0.020032</size>
            </box>
          </geometry>
          <material>
            <ambient>0.5 0.3 0.1 1</ambient>
          </material>
        </visual>
        <self_collide>0</self_collide>
        <enable_wind>0</enable_wind>
        <kinematic>0</kinematic>
      </link>
      <pose>-0.4 -0.8 0.010016 0 -0 0</pose>
    </model>
    <model name='terrain_block_2_1'>
      <static>1</static>
      <link name='link'>
        <collision name='collision'>
          <geometry>
            <box>
              <size>0.19 0.19 0.035666</size>
            </box>
          </geometry>
          <max_contacts>10</max_contacts>
          <surface>
            <contact>
              <ode/>
            </contact>
            <bounce/>
            <friction>
              <torsional>
                <ode/>
              </torsional>
              <ode/>
            </friction>
          </surface>
        </collision>
        <visual name='visual'>
          <geometry>
            <box>
              <size>0.19 0.19 0.035666</size>
            </box>
          </geometry>
          <material>
            <ambient>0.5 0.3 0.1 1</ambient>
          </material>
        </visual>
        <self_collide>0</self_collide>
        <enable_wind>0</enable_wind>
        <kinematic>0</kinematic>
      </link>
      <pose>-0.4 -0.6 0.017833 0 -0 0</pose>
    </model>
    <model name='terrain_block_2_2'>
      <static>1</static>
      <link name='link'>
        <collision name='collision'>
          <geometry>
            <box>
              <size>0.19 0.19 0.062141</size>
            </box>
          </geometry>
          <max_contacts>10</max_contacts>
          <surface>
            <contact>
              <ode/>
            </contact>
            <bounce/>
            <friction>
              <torsional>
                <ode/>
              </torsional>
              <ode/>
            </friction>
          </surface>
        </collision>
        <visual name='visual'>
          <geometry>
            <box>
              <size>0.19 0.19 0.062141</size>
            </box>
          </geometry>
          <material>
            <ambient>0.5 0.3 0.1 1</ambient>
          </material>
        </visual>
        <self_collide>0</self_collide>
        <enable_wind>0</enable_wind>
        <kinematic>0</kinematic>
      </link>
      <pose>-0.4 -0.4 0.031071 0 -0 0</pose>
    </model>
    <model name='terrain_block_2_3'>
      <static>1</static>
      <link name='link'>
        <collision name='collision'>
          <geometry>
            <box>
              <size>0.19 0.19 0.022664</size>
            </box>
          </geometry>
          <max_contacts>10</max_contacts>
          <surface>
            <contact>
              <ode/>
            </contact>
            <bounce/>
            <friction>
              <torsional>
                <ode/>
              </torsional>
              <ode/>
            </friction>
          </surface>
        </collision>
        <visual name='visual'>
          <geometry>
            <box>
              <size>0.19 0.19 0.022664</size>
            </box>
          </geometry>
          <material>
            <ambient>0.5 0.3 0.1 1</ambient>
          </material>
        </visual>
        <self_collide>0</self_collide>
        <enable_wind>0</enable_wind>
        <kinematic>0</kinematic>
      </link>
      <pose>-0.4 -0.2 0.011332 0 -0 0</pose>
    </model>
    <model name='terrain_block_2_4'>
      <static>1</static>
      <link name='link'>
        <collision name='collision'>
          <geometry>
            <box>
              <size>0.19 0.19 0.0294</size>
            </box>
          </geometry>
          <max_contacts>10</max_contacts>
          <surface>
            <contact>
              <ode/>
            </contact>
            <bounce/>
            <friction>
              <torsional>
                <ode/>
              </torsional>
              <ode/>
            </friction>
          </surface>
        </collision>
        <visual name='visual'>
          <geometry>
            <box>
              <size>0.19 0.19 0.0294</size>
            </box>
          </geometry>
          <material>
            <ambient>0.5 0.3 0.1 1</ambient>
          </material>
        </visual>
        <self_collide>0</self_collide>
        <enable_wind>0</enable_wind>
        <kinematic>0</kinematic>
      </link>
      <pose>-0.4 0 0.0147 0 -0 0</pose>
    </model>
    <model name='terrain_block_2_5'>
      <static>1</static>
      <link name='link'>
        <collision name='collision'>
          <geometry>
            <box>
              <size>0.19 0.19 0.063957</size>
            </box>
          </geometry>
          <max_contacts>10</max_contacts>
          <surface>
            <contact>
              <ode/>
            </contact>
            <bounce/>
            <friction>
              <torsional>
                <ode/>
              </torsional>
              <ode/>
            </friction>
          </surface>
        </collision>
        <visual name='visual'>
          <geometry>
            <box>
              <size>0.19 0.19 0.063957</size>
            </box>
          </geometry>
          <material>
            <ambient>0.5 0.3 0.1 1</ambient>
          </material>
        </visual>
        <self_collide>0</self_collide>
        <enable_wind>0</enable_wind>
        <kinematic>0</kinematic>
      </link>
      <pose>-0.4 0.2 0.031978 0 -0 0</pose>
    </model>
    <model name='terrain_block_2_6'>
      <static>1</static>
      <link name='link'>
        <collision name='collision'>
          <geometry>
            <box>
              <size>0.19 0.19 0.05213</size>
            </box>
          </geometry>
          <max_contacts>10</max_contacts>
          <surface>
            <contact>
              <ode/>
            </contact>
            <bounce/>
            <friction>
              <torsional>
                <ode/>
              </torsional>
              <ode/>
            </friction>
          </surface>
        </collision>
        <visual name='visual'>
          <geometry>
            <box>
              <size>0.19 0.19 0.05213</size>
            </box>
          </geometry>
          <material>
            <ambient>0.5 0.3 0.1 1</ambient>
          </material>
        </visual>
        <self_collide>0</self_collide>
        <enable_wind>0</enable_wind>
        <kinematic>0</kinematic>
      </link>
      <pose>-0.4 0.4 0.026065 0 -0 0</pose>
    </model>
    <model name='terrain_block_2_7'>
      <static>1</static>
      <link name='link'>
        <collision name='collision'>
          <geometry>
            <box>
              <size>0.19 0.19 0.030254</size>
            </box>
          </geometry>
          <max_contacts>10</max_contacts>
          <surface>
            <contact>
              <ode/>
            </contact>
            <bounce/>
            <friction>
              <torsional>
                <ode/>
              </torsional>
              <ode/>
            </friction>
          </surface>
        </collision>
        <visual name='visual'>
          <geometry>
            <box>
              <size>0.19 0.19 0.030254</size>
            </box>
          </geometry>
          <material>
            <ambient>0.5 0.3 0.1 1</ambient>
          </material>
        </visual>
        <self_collide>0</self_collide>
        <enable_wind>0</enable_wind>
        <kinematic>0</kinematic>
      </link>
      <pose>-0.4 0.6 0.015127 0 -0 0</pose>
    </model>
    <model name='terrain_block_3_0'>
      <static>1</static>
      <link name='link'>
        <collision name='collision'>
          <geometry>
            <box>
              <size>0.19 0.19 0.025856</size>
            </box>
          </geometry>
          <max_contacts>10</max_contacts>
          <surface>
            <contact>
              <ode/>
            </contact>
            <bounce/>
            <friction>
              <torsional>
                <ode/>
              </torsional>
              <ode/>
            </friction>
          </surface>
        </collision>
        <visual name='visual'>
          <geometry>
            <box>
              <size>0.19 0.19 0.025856</size>
            </box>
          </geometry>
          <material>
            <ambient>0.5 0.3 0.1 1</ambient>
          </material>
        </visual>
        <self_collide>0</self_collide>
        <enable_wind>0</enable_wind>
        <kinematic>0</kinematic>
      </link>
      <pose>-0.2 -0.8 0.012928 0 -0 0</pose>
    </model>
    <model name='terrain_block_3_1'>
      <static>1</static>
      <link name='link'>
        <collision name='collision'>
          <geometry>
            <box>
              <size>0.19 0.19 0.064584</size>
            </box>
          </geometry>
          <max_contacts>10</max_contacts>
          <surface>
            <contact>
              <ode/>
            </contact>
            <bounce/>
            <friction>
              <torsional>
                <ode/>
              </torsional>
              <ode/>
            </friction>
          </surface>
        </collision>
        <visual name='visual'>
          <geometry>
            <box>
              <size>0.19 0.19 0.064584</size>
            </box>
          </geometry>
          <material>
            <ambient>0.5 0.3 0.1 1</ambient>
          </material>
        </visual>
        <self_collide>0</self_collide>
        <enable_wind>0</enable_wind>
        <kinematic>0</kinematic>
      </link>
      <pose>-0.2 -0.6 0.032292 0 -0 0</pose>
    </model>
    <model name='terrain_block_3_2'>
      <static>1</static>
      <link name='link'>
        <collision name='collision'>
          <geometry>
            <box>
              <size>0.19 0.19 0.030738</size>
            </box>
          </geometry>
          <max_contacts>10</max_contacts>
          <surface>
            <contact>
              <ode/>
            </contact>
            <bounce/>
            <friction>
              <torsional>
                <ode/>
              </torsional>
              <ode/>
            </friction>
          </surface>
        </collision>
        <visual name='visual'>
          <geometry>
            <box>
              <size>0.19 0.19 0.030738</size>
            </box>
          </geometry>
          <material>
            <ambient>0.5 0.3 0.1 1</ambient>
          </material>
        </visual>
        <self_collide>0</self_collide>
        <enable_wind>0</enable_wind>
        <kinematic>0</kinematic>
      </link>
      <pose>-0.2 -0.4 0.015369 0 -0 0</pose>
    </model>
    <model name='terrain_block_3_3'>
      <static>1</static>
      <link name='link'>
        <collision name='collision'>
          <geometry>
            <box>
              <size>0.19 0.19 0.060856</size>
            </box>
          </geometry>
          <max_contacts>10</max_contacts>
          <surface>
            <contact>
              <ode/>
            </contact>
            <bounce/>
            <friction>
              <torsional>
                <ode/>
              </torsional>
              <ode/>
            </friction>
          </surface>
        </collision>
        <visual name='visual'>
          <geometry>
            <box>
              <size>0.19 0.19 0.060856</size>
            </box>
          </geometry>
          <material>
            <ambient>0.5 0.3 0.1 1</ambient>
          </material>
        </visual>
        <self_collide>0</self_collide>
        <enable_wind>0</enable_wind>
        <kinematic>0</kinematic>
      </link>
      <pose>-0.2 -0.2 0.030428 0 -0 0</pose>
    </model>
    <model name='terrain_block_3_4'>
      <static>1</static>
      <link name='link'>
        <collision name='collision'>
          <geometry>
            <box>
              <size>0.19 0.19 0.02964</size>
            </box>
          </geometry>
          <max_contacts>10</max_contacts>
          <surface>
            <contact>
              <ode/>
            </contact>
            <bounce/>
            <friction>
              <torsional>
                <ode/>
              </torsional>
              <ode/>
            </friction>
          </surface>
        </collision>
        <visual name='visual'>
          <geometry>
            <box>
              <size>0.19 0.19 0.02964</size>
            </box>
          </geometry>
          <material>
            <ambient>0.5 0.3 0.1 1</ambient>
          </material>
        </visual>
        <self_collide>0</self_collide>
        <enable_wind>0</enable_wind>
        <kinematic>0</kinematic>
      </link>
      <pose>-0.2 0 0.01482 0 -0 0</pose>
    </model>
    <model name='terrain_block_3_5'>
      <static>1</static>
      <link name='link'>
        <collision name='collision'>
          <geometry>
            <box>
              <size>0.19 0.19 0.064661</size>
            </box>
          </geometry>
          <max_contacts>10</max_contacts>
          <surface>
            <contact>
              <ode/>
            </contact>
            <bounce/>
            <friction>
              <torsional>
                <ode/>
              </torsional>
              <ode/>
            </friction>
          </surface>
        </collision>
        <visual name='visual'>
          <geometry>
            <box>
              <size>0.19 0.19 0.064661</size>
            </box>
          </geometry>
          <material>
            <ambient>0.5 0.3 0.1 1</ambient>
          </material>
        </visual>
        <self_collide>0</self_collide>
        <enable_wind>0</enable_wind>
        <kinematic>0</kinematic>
      </link>
      <pose>-0.2 0.2 0.032331 0 -0 0</pose>
    </model>
    <model name='terrain_block_3_6'>
      <static>1</static>
      <link name='link'>
        <collision name='collision'>
          <geometry>
            <box>
              <size>0.19 0.19 0.052943</size>
            </box>
          </geometry>
          <max_contacts>10</max_contacts>
          <surface>
            <contact>
              <ode/>
            </contact>
            <bounce/>
            <friction>
              <torsional>
                <ode/>
              </torsional>
              <ode/>
            </friction>
          </surface>
        </collision>
        <visual name='visual'>
          <geometry>
            <box>
              <size>0.19 0.19 0.052943</size>
            </box>
          </geometry>
          <material>
            <ambient>0.5 0.3 0.1 1</ambient>
          </material>
        </visual>
        <self_collide>0</self_collide>
        <enable_wind>0</enable_wind>
        <kinematic>0</kinematic>
      </link>
      <pose>-0.2 0.4 0.026472 0 -0 0</pose>
    </model>
    <model name='terrain_block_3_7'>
      <static>1</static>
      <link name='link'>
        <collision name='collision'>
          <geometry>
            <box>
              <size>0.19 0.19 0.042059</size>
            </box>
          </geometry>
          <max_contacts>10</max_contacts>
          <surface>
            <contact>
              <ode/>
            </contact>
            <bounce/>
            <friction>
              <torsional>
                <ode/>
              </torsional>
              <ode/>
            </friction>
          </surface>
        </collision>
        <visual name='visual'>
          <geometry>
            <box>
              <size>0.19 0.19 0.042059</size>
            </box>
          </geometry>
          <material>
            <ambient>0.5 0.3 0.1 1</ambient>
          </material>
        </visual>
        <self_collide>0</self_collide>
        <enable_wind>0</enable_wind>
        <kinematic>0</kinematic>
      </link>
      <pose>-0.2 0.6 0.02103 0 -0 0</pose>
    </model>
    <model name='terrain_block_4_0'>
      <static>1</static>
      <link name='link'>
        <collision name='collision'>
          <geometry>
            <box>
              <size>0.19 0.19 0.056214</size>
            </box>
          </geometry>
          <max_contacts>10</max_contacts>
          <surface>
            <contact>
              <ode/>
            </contact>
            <bounce/>
            <friction>
              <torsional>
                <ode/>
              </torsional>
              <ode/>
            </friction>
          </surface>
        </collision>
        <visual name='visual'>
          <geometry>
            <box>
              <size>0.19 0.19 0.056214</size>
            </box>
          </geometry>
          <material>
            <ambient>0.5 0.3 0.1 1</ambient>
          </material>
        </visual>
        <self_collide>0</self_collide>
        <enable_wind>0</enable_wind>
        <kinematic>0</kinematic>
      </link>
      <pose>0 -0.8 0.028107 0 -0 0</pose>
    </model>
    <model name='terrain_block_4_1'>
      <static>1</static>
      <link name='link'>
        <collision name='collision'>
          <geometry>
            <box>
              <size>0.19 0.19 0.055141</size>
            </box>
          </geometry>
          <max_contacts>10</max_contacts>
          <surface>
            <contact>
              <ode/>
            </contact>
            <bounce/>
            <friction>
              <torsional>
                <ode/>
              </torsional>
              <ode/>
            </friction>
          </surface>
        </collision>
        <visual name='visual'>
          <geometry>
            <box>
              <size>0.19 0.19 0.055141</size>
            </box>
          </geometry>
          <material>
            <ambient>0.5 0.3 0.1 1</ambient>
          </material>
        </visual>
        <self_collide>0</self_collide>
        <enable_wind>0</enable_wind>
        <kinematic>0</kinematic>
      </link>
      <pose>0 -0.6 0.02757 0 -0 0</pose>
    </model>
    <model name='terrain_block_4_2'>
      <static>1</static>
      <link name='link'>
        <collision name='collision'>
          <geometry>
            <box>
              <size>0.19 0.19 0.055357</size>
            </box>
          </geometry>
          <max_contacts>10</max_contacts>
          <surface>
            <contact>
              <ode/>
            </contact>
            <bounce/>
            <friction>
              <torsional>
                <ode/>
              </torsional>
              <ode/>
            </friction>
          </surface>
        </collision>
        <visual name='visual'>
          <geometry>
            <box>
              <size>0.19 0.19 0.055357</size>
            </box>
          </geometry>
          <material>
            <ambient>0.5 0.3 0.1 1</ambient>
          </material>
        </visual>
        <self_collide>0</self_collide>
        <enable_wind>0</enable_wind>
        <kinematic>0</kinematic>
      </link>
      <pose>0 -0.4 0.027678 0 -0 0</pose>
    </model>
    <model name='terrain_block_4_3'>
      <static>1</static>
      <link name='link'>
        <collision name='collision'>
          <geometry>
            <box>
              <size>0.19 0.19 0.053225</size>
            </box>
          </geometry>
          <max_contacts>10</max_contacts>
          <surface>
            <contact>
              <ode/>
            </contact>
            <bounce/>
            <friction>
              <torsional>
                <ode/>
              </torsional>
              <ode/>
            </friction>
          </surface>
        </collision>
        <visual name='visual'>
          <geometry>
            <box>
              <size>0.19 0.19 0.053225</size>
            </box>
          </geometry>
          <material>
            <ambient>0.5 0.3 0.1 1</ambient>
          </material>
        </visual>
        <self_collide>0</self_collide>
        <enable_wind>0</enable_wind>
        <kinematic>0</kinematic>
      </link>
      <pose>0 -0.2 0.026613 0 -0 0</pose>
    </model>
    <model name='terrain_block_4_4'>
      <static>1</static>
      <link name='link'>
        <collision name='collision'>
          <geometry>
            <box>
              <size>0.19 0.19 0.043869</size>
            </box>
          </geometry>
          <max_contacts>10</max_contacts>
          <surface>
            <contact>
              <ode/>
            </contact>
            <bounce/>
            <friction>
              <torsional>
                <ode/>
              </torsional>
              <ode/>
            </friction>
          </surface>
        </collision>
        <visual name='visual'>
          <geometry>
            <box>
              <size>0.19 0.19 0.043869</size>
            </box>
          </geometry>
          <material>
            <ambient>0.5 0.3 0.1 1</ambient>
          </material>
        </visual>
        <self_collide>0</self_collide>
        <enable_wind>0</enable_wind>
        <kinematic>0</kinematic>
      </link>
      <pose>0 0 0.021934 0 -0 0</pose>
    </model>
    <model name='terrain_block_4_5'>
      <static>1</static>
      <link name='link'>
        <collision name='collision'>
          <geometry>
            <box>
              <size>0.19 0.19 0.033668</size>
            </box>
          </geometry>
          <max_contacts>10</max_contacts>
          <surface>
            <contact>
              <ode/>
            </contact>
            <bounce/>
            <friction>
              <torsional>
                <ode/>
              </torsional>
              <ode/>
            </friction>
          </surface>
        </collision>
        <visual name='visual'>
          <geometry>
            <box>
              <size>0.19 0.19 0.033668</size>
            </box>
          </geometry>
          <material>
            <ambient>0.5 0.3 0.1 1</ambient>
          </material>
        </visual>
        <self_collide>0</self_collide>
        <enable_wind>0</enable_wind>
        <kinematic>0</kinematic>
      </link>
      <pose>0 0.2 0.016834 0 -0 0</pose>
    </model>
    <model name='terrain_block_4_6'>
      <static>1</static>
      <link name='link'>
        <collision name='collision'>
          <geometry>
            <box>
              <size>0.19 0.19 0.047347</size>
            </box>
          </geometry>
          <max_contacts>10</max_contacts>
          <surface>
            <contact>
              <ode/>
            </contact>
            <bounce/>
            <friction>
              <torsional>
                <ode/>
              </torsional>
              <ode/>
            </friction>
          </surface>
        </collision>
        <visual name='visual'>
          <geometry>
            <box>
              <size>0.19 0.19 0.047347</size>
            </box>
          </geometry>
          <material>
            <ambient>0.5 0.3 0.1 1</ambient>
          </material>
        </visual>
        <self_collide>0</self_collide>
        <enable_wind>0</enable_wind>
        <kinematic>0</kinematic>
      </link>
      <pose>0 0.4 0.023674 0 -0 0</pose>
    </model>
    <model name='terrain_block_4_7'>
      <static>1</static>
      <link name='link'>
        <collision name='collision'>
          <geometry>
            <box>
              <size>0.19 0.19 0.024173</size>
            </box>
          </geometry>
          <max_contacts>10</max_contacts>
          <surface>
            <contact>
              <ode/>
            </contact>
            <bounce/>
            <friction>
              <torsional>
                <ode/>
              </torsional>
              <ode/>
            </friction>
          </surface>
        </collision>
        <visual name='visual'>
          <geometry>
            <box>
              <size>0.19 0.19 0.024173</size>
            </box>
          </geometry>
          <material>
            <ambient>0.5 0.3 0.1 1</ambient>
          </material>
        </visual>
        <self_collide>0</self_collide>
        <enable_wind>0</enable_wind>
        <kinematic>0</kinematic>
      </link>
      <pose>0 0.6 0.012086 0 -0 0</pose>
    </model>
    <model name='terrain_block_5_0'>
      <static>1</static>
      <link name='link'>
        <collision name='collision'>
          <geometry>
            <box>
              <size>0.19 0.19 0.029443</size>
            </box>
          </geometry>
          <max_contacts>10</max_contacts>
          <surface>
            <contact>
              <ode/>
            </contact>
            <bounce/>
            <friction>
              <torsional>
                <ode/>
              </torsional>
              <ode/>
            </friction>
          </surface>
        </collision>
        <visual name='visual'>
          <geometry>
            <box>
              <size>0.19 0.19 0.029443</size>
            </box>
          </geometry>
          <material>
            <ambient>0.5 0.3 0.1 1</ambient>
          </material>
        </visual>
        <self_collide>0</self_collide>
        <enable_wind>0</enable_wind>
        <kinematic>0</kinematic>
      </link>
      <pose>0.2 -0.8 0.014721 0 -0 0</pose>
    </model>
    <model name='terrain_block_5_1'>
      <static>1</static>
      <link name='link'>
        <collision name='collision'>
          <geometry>
            <box>
              <size>0.19 0.19 0.045294</size>
            </box>
          </geometry>
          <max_contacts>10</max_contacts>
          <surface>
            <contact>
              <ode/>
            </contact>
            <bounce/>
            <friction>
              <torsional>
                <ode/>
              </torsional>
              <ode/>
            </friction>
          </surface>
        </collision>
        <visual name='visual'>
          <geometry>
            <box>
              <size>0.19 0.19 0.045294</size>
            </box>
          </geometry>
          <material>
            <ambient>0.5 0.3 0.1 1</ambient>
          </material>
        </visual>
        <self_collide>0</self_collide>
        <enable_wind>0</enable_wind>
        <kinematic>0</kinematic>
      </link>
      <pose>0.2 -0.6 0.022647 0 -0 0</pose>
    </model>
    <model name='terrain_block_5_2'>
      <static>1</static>
      <link name='link'>
        <collision name='collision'>
          <geometry>
            <box>
              <size>0.19 0.19 0.025688</size>
            </box>
          </geometry>
          <max_contacts>10</max_contacts>
          <surface>
            <contact>
              <ode/>
            </contact>
            <bounce/>
            <friction>
              <torsional>
                <ode/>
              </torsional>
              <ode/>
            </friction>
          </surface>
        </collision>
        <visual name='visual'>
          <geometry>
            <box>
              <size>0.19 0.19 0.025688</size>
            </box>
          </geometry>
          <material>
            <ambient>0.5 0.3 0.1 1</ambient>
          </material>
        </visual>
        <self_collide>0</self_collide>
        <enable_wind>0</enable_wind>
        <kinematic>0</kinematic>
      </link>
      <pose>0.2 -0.4 0.012844 0 -0 0</pose>
    </model>
    <model name='terrain_block_5_3'>
      <static>1</static>
      <link name='link'>
        <collision name='collision'>
          <geometry>
            <box>
              <size>0.19 0.19 0.04275</size>
            </box>
          </geometry>
          <max_contacts>10</max_contacts>
          <surface>
            <contact>
              <ode/>
            </contact>
            <bounce/>
            <friction>
              <torsional>
                <ode/>
              </torsional>
              <ode/>
            </friction>
          </surface>
        </collision>
        <visual name='visual'>
          <geometry>
            <box>
              <size>0.19 0.19 0.04275</size>
            </box>
          </geometry>
          <material>
            <ambient>0.5 0.3 0.1 1</ambient>
          </material>
        </visual>
        <self_collide>0</self_collide>
        <enable_wind>0</enable_wind>
        <kinematic>0</kinematic>
      </link>
      <pose>0.2 -0.2 0.021375 0 -0 0</pose>
    </model>
    <model name='terrain_block_5_4'>
      <static>1</static>
      <link name='link'>
        <collision name='collision'>
          <geometry>
            <box>
              <size>0.19 0.19 0.035828</size>
            </box>
          </geometry>
          <max_contacts>10</max_contacts>
          <surface>
            <contact>
              <ode/>
            </contact>
            <bounce/>
            <friction>
              <torsional>
                <ode/>
              </torsional>
              <ode/>
            </friction>
          </surface>
        </collision>
        <visual name='visual'>
          <geometry>
            <box>
              <size>0.19 0.19 0.035828</size>
            </box>
          </geometry>
          <material>
            <ambient>0.5 0.3 0.1 1</ambient>
          </material>
        </visual>
        <self_collide>0</self_collide>
        <enable_wind>0</enable_wind>
        <kinematic>0</kinematic>
      </link>
      <pose>0.2 0 0.017914 0 -0 0</pose>
    </model>
    <model name='terrain_block_5_5'>
      <static>1</static>
      <link name='link'>
        <collision name='collision'>
          <geometry>
            <box>
              <size>0.19 0.19 0.04485</size>
            </box>
          </geometry>
          <max_contacts>10</max_contacts>
          <surface>
            <contact>
              <ode/>
            </contact>
            <bounce/>
            <friction>
              <torsional>
                <ode/>
              </torsional>
              <ode/>
            </friction>
          </surface>
        </collision>
        <visual name='visual'>
          <geometry>
            <box>
              <size>0.19 0.19 0.04485</size>
            </box>
          </geometry>
          <material>
            <ambient>0.5 0.3 0.1 1</ambient>
          </material>
        </visual>
        <self_collide>0</self_collide>
        <enable_wind>0</enable_wind>
        <kinematic>0</kinematic>
      </link>
      <pose>0.2 0.2 0.022425 0 -0 0</pose>
    </model>
    <model name='terrain_block_5_6'>
      <static>1</static>
      <link name='link'>
        <collision name='collision'>
          <geometry>
            <box>
              <size>0.19 0.19 0.044194</size>
            </box>
          </geometry>
          <max_contacts>10</max_contacts>
          <surface>
            <contact>
              <ode/>
            </contact>
            <bounce/>
            <friction>
              <torsional>
                <ode/>
              </torsional>
              <ode/>
            </friction>
          </surface>
        </collision>
        <visual name='visual'>
          <geometry>
            <box>
              <size>0.19 0.19 0.044194</size>
            </box>
          </geometry>
          <material>
            <ambient>0.5 0.3 0.1 1</ambient>
          </material>
        </visual>
        <self_collide>0</self_collide>
        <enable_wind>0</enable_wind>
        <kinematic>0</kinematic>
      </link>
      <pose>0.2 0.4 0.022097 0 -0 0</pose>
    </model>
    <model name='terrain_block_5_7'>
      <static>1</static>
      <link name='link'>
        <collision name='collision'>
          <geometry>
            <box>
              <size>0.19 0.19 0.046383</size>
            </box>
          </geometry>
          <max_contacts>10</max_contacts>
          <surface>
            <contact>
              <ode/>
            </contact>
            <bounce/>
            <friction>
              <torsional>
                <ode/>
              </torsional>
              <ode/>
            </friction>
          </surface>
        </collision>
        <visual name='visual'>
          <geometry>
            <box>
              <size>0.19 0.19 0.046383</size>
            </box>
          </geometry>
          <material>
            <ambient>0.5 0.3 0.1 1</ambient>
          </material>
        </visual>
        <self_collide>0</self_collide>
        <enable_wind>0</enable_wind>
        <kinematic>0</kinematic>
      </link>
      <pose>0.2 0.6 0.023192 0 -0 0</pose>
    </model>
    <model name='terrain_block_6_0'>
      <static>1</static>
      <link name='link'>
        <collision name='collision'>
          <geometry>
            <box>
              <size>0.19 0.19 0.062726</size>
            </box>
          </geometry>
          <max_contacts>10</max_contacts>
          <surface>
            <contact>
              <ode/>
            </contact>
            <bounce/>
            <friction>
              <torsional>
                <ode/>
              </torsional>
              <ode/>
            </friction>
          </surface>
        </collision>
        <visual name='visual'>
          <geometry>
            <box>
              <size>0.19 0.19 0.062726</size>
            </box>
          </geometry>
          <material>
            <ambient>0.5 0.3 0.1 1</ambient>
          </material>
        </visual>
        <self_collide>0</self_collide>
        <enable_wind>0</enable_wind>
        <kinematic>0</kinematic>
      </link>
      <pose>0.4 -0.8 0.031363 0 -0 0</pose>
    </model>
    <model name='terrain_block_6_1'>
      <static>1</static>
      <link name='link'>
        <collision name='collision'>
          <geometry>
            <box>
              <size>0.19 0.19 0.034861</size>
            </box>
          </geometry>
          <max_contacts>10</max_contacts>
          <surface>
            <contact>
              <ode/>
            </contact>
            <bounce/>
            <friction>
              <torsional>
                <ode/>
              </torsional>
              <ode/>
            </friction>
          </surface>
        </collision>
        <visual name='visual'>
          <geometry>
            <box>
              <size>0.19 0.19 0.034861</size>
            </box>
          </geometry>
          <material>
            <ambient>0.5 0.3 0.1 1</ambient>
          </material>
        </visual>
        <self_collide>0</self_collide>
        <enable_wind>0</enable_wind>
        <kinematic>0</kinematic>
      </link>
      <pose>0.4 -0.6 0.01743 0 -0 0</pose>
    </model>
    <model name='terrain_block_6_2'>
      <static>1</static>
      <link name='link'>
        <collision name='collision'>
          <geometry>
            <box>
              <size>0.19 0.19 0.047311</size>
            </box>
          </geometry>
          <max_contacts>10</max_contacts>
          <surface>
            <contact>
              <ode/>
            </contact>
            <bounce/>
            <friction>
              <torsional>
                <ode/>
              </torsional>
              <ode/>
            </friction>
          </surface>
        </collision>
        <visual name='visual'>
          <geometry>
            <box>
              <size>0.19 0.19 0.047311</size>
            </box>
          </geometry>
          <material>
            <ambient>0.5 0.3 0.1 1</ambient>
          </material>
        </visual>
        <self_collide>0</self_collide>
        <enable_wind>0</enable_wind>
        <kinematic>0</kinematic>
      </link>
      <pose>0.4 -0.4 0.023655 0 -0 0</pose>
    </model>
    <model name='terrain_block_6_3'>
      <static>1</static>
      <link name='link'>
        <collision name='collision'>
          <geometry>
            <box>
              <size>0.19 0.19 0.069465</size>
            </box>
          </geometry>
          <max_contacts>10</max_contacts>
          <surface>
            <contact>
              <ode/>
            </contact>
            <bounce/>
            <friction>
              <torsional>
                <ode/>
              </torsional>
              <ode/>
            </friction>
          </surface>
        </collision>
        <visual name='visual'>
          <geometry>
            <box>
              <size>0.19 0.19 0.069465</size>
            </box>
          </geometry>
          <material>
            <ambient>0.5 0.3 0.1 1</ambient>
          </material>
        </visual>
        <self_collide>0</self_collide>
        <enable_wind>0</enable_wind>
        <kinematic>0</kinematic>
      </link>
      <pose>0.4 -0.2 0.034733 0 -0 0</pose>
    </model>
    <model name='terrain_block_6_4'>
      <static>1</static>
      <link name='link'>
        <collision name='collision'>
          <geometry>
            <box>
              <size>0.19 0.19 0.025831</size>
            </box>
          </geometry>
          <max_contacts>10</max_contacts>
          <surface>
            <contact>
              <ode/>
            </contact>
            <bounce/>
            <friction>
              <torsional>
                <ode/>
              </torsional>
              <ode/>
            </friction>
          </surface>
        </collision>
        <visual name='visual'>
          <geometry>
            <box>
              <size>0.19 0.19 0.025831</size>
            </box>
          </geometry>
          <material>
            <ambient>0.5 0.3 0.1 1</ambient>
          </material>
        </visual>
        <self_collide>0</self_collide>
        <enable_wind>0</enable_wind>
        <kinematic>0</kinematic>
      </link>
      <pose>0.4 0 0.012916 0 -0 0</pose>
    </model>
    <model name='terrain_block_6_5'>
      <static>1</static>
      <link name='link'>
        <collision name='collision'>
          <geometry>
            <box>
              <size>0.19 0.19 0.06354</size>
            </box>
          </geometry>
          <max_contacts>10</max_contacts>
          <surface>
            <contact>
              <ode/>
            </contact>
            <bounce/>
            <friction>
              <torsional>
                <ode/>
              </torsional>
              <ode/>
            </friction>
          </surface>
        </collision>
        <visual name='visual'>
          <geometry>
            <box>
              <size>0.19 0.19 0.06354</size>
            </box>
          </geometry>
          <material>
            <ambient>0.5 0.3 0.1 1</ambient>
          </material>
        </visual>
        <self_collide>0</self_collide>
        <enable_wind>0</enable_wind>
        <kinematic>0</kinematic>
      </link>
      <pose>0.4 0.2 0.03177 0 -0 0</pose>
    </model>
    <model name='terrain_block_6_6'>
      <static>1</static>
      <link name='link'>
        <collision name='collision'>
          <geometry>
            <box>
              <size>0.19 0.19 0.058648</size>
            </box>
          </geometry>
          <max_contacts>10</max_contacts>
          <surface>
            <contact>
              <ode/>
            </contact>
            <bounce/>
            <friction>
              <torsional>
                <ode/>
              </torsional>
              <ode/>
            </friction>
          </surface>
        </collision>
        <visual name='visual'>
          <geometry>
            <box>
              <size>0.19 0.19 0.058648</size>
            </box>
          </geometry>
          <material>
            <ambient>0.5 0.3 0.1 1</ambient>
          </material>
        </visual>
        <self_collide>0</self_collide>
        <enable_wind>0</enable_wind>
        <kinematic>0</kinematic>
      </link>
      <pose>0.4 0.4 0.029324 0 -0 0</pose>
    </model>
    <model name='terrain_block_6_7'>
      <static>1</static>
      <link name='link'>
        <collision name='collision'>
          <geometry>
            <box>
              <size>0.19 0.19 0.028103</size>
            </box>
          </geometry>
          <max_contacts>10</max_contacts>
          <surface>
            <contact>
              <ode/>
            </contact>
            <bounce/>
            <friction>
              <torsional>
                <ode/>
              </torsional>
              <ode/>
            </friction>
          </surface>
        </collision>
        <visual name='visual'>
          <geometry>
            <box>
              <size>0.19 0.19 0.028103</size>
            </box>
          </geometry>
          <material>
            <ambient>0.5 0.3 0.1 1</ambient>
          </material>
        </visual>
        <self_collide>0</self_collide>
        <enable_wind>0</enable_wind>
        <kinematic>0</kinematic>
      </link>
      <pose>0.4 0.6 0.014052 0 -0 0</pose>
    </model>
    <model name='terrain_block_7_0'>
      <static>1</static>
      <link name='link'>
        <collision name='collision'>
          <geometry>
            <box>
              <size>0.19 0.19 0.024411</size>
            </box>
          </geometry>
          <max_contacts>10</max_contacts>
          <surface>
            <contact>
              <ode/>
            </contact>
            <bounce/>
            <friction>
              <torsional>
                <ode/>
              </torsional>
              <ode/>
            </friction>
          </surface>
        </collision>
        <visual name='visual'>
          <geometry>
            <box>
              <size>0.19 0.19 0.024411</size>
            </box>
          </geometry>
          <material>
            <ambient>0.5 0.3 0.1 1</ambient>
          </material>
        </visual>
        <self_collide>0</self_collide>
        <enable_wind>0</enable_wind>
        <kinematic>0</kinematic>
      </link>
      <pose>0.6 -0.8 0.012205 0 -0 0</pose>
    </model>
    <model name='terrain_block_7_1'>
      <static>1</static>
      <link name='link'>
        <collision name='collision'>
          <geometry>
            <box>
              <size>0.19 0.19 0.062386</size>
            </box>
          </geometry>
          <max_contacts>10</max_contacts>
          <surface>
            <contact>
              <ode/>
            </contact>
            <bounce/>
            <friction>
              <torsional>
                <ode/>
              </torsional>
              <ode/>
            </friction>
          </surface>
        </collision>
        <visual name='visual'>
          <geometry>
            <box>
              <size>0.19 0.19 0.062386</size>
            </box>
          </geometry>
          <material>
            <ambient>0.5 0.3 0.1 1</ambient>
          </material>
        </visual>
        <self_collide>0</self_collide>
        <enable_wind>0</enable_wind>
        <kinematic>0</kinematic>
      </link>
      <pose>0.6 -0.6 0.031193 0 -0 0</pose>
    </model>
    <model name='terrain_block_7_2'>
      <static>1</static>
      <link name='link'>
        <collision name='collision'>
          <geometry>
            <box>
              <size>0.19 0.19 0.065979</size>
            </box>
          </geometry>
          <max_contacts>10</max_contacts>
          <surface>
            <contact>
              <ode/>
            </contact>
            <bounce/>
            <friction>
              <torsional>
                <ode/>
              </torsional>
              <ode/>
            </friction>
          </surface>
        </collision>
        <visual name='visual'>
          <geometry>
            <box>
              <size>0.19 0.19 0.065979</size>
            </box>
          </geometry>
          <material>
            <ambient>0.5 0.3 0.1 1</ambient>
          </material>
        </visual>
        <self_collide>0</self_collide>
        <enable_wind>0</enable_wind>
        <kinematic>0</kinematic>
      </link>
      <pose>0.6 -0.4 0.03299 0 -0 0</pose>
    </model>
    <model name='terrain_block_7_3'>
      <static>1</static>
      <link name='link'>
        <collision name='collision'>
          <geometry>
            <box>
              <size>0.19 0.19 0.067923</size>
            </box>
          </geometry>
          <max_contacts>10</max_contacts>
          <surface>
            <contact>
              <ode/>
            </contact>
            <bounce/>
            <friction>
              <torsional>
                <ode/>
              </torsional>
              <ode/>
            </friction>
          </surface>
        </collision>
        <visual name='visual'>
          <geometry>
            <box>
              <size>0.19 0.19 0.067923</size>
            </box>
          </geometry>
          <material>
            <ambient>0.5 0.3 0.1 1</ambient>
          </material>
        </visual>
        <self_collide>0</self_collide>
        <enable_wind>0</enable_wind>
        <kinematic>0</kinematic>
      </link>
      <pose>0.6 -0.2 0.033962 0 -0 0</pose>
    </model>
    <model name='terrain_block_7_4'>
      <static>1</static>
      <link name='link'>
        <collision name='collision'>
          <geometry>
            <box>
              <size>0.19 0.19 0.048782</size>
            </box>
          </geometry>
          <max_contacts>10</max_contacts>
          <surface>
            <contact>
              <ode/>
            </contact>
            <bounce/>
            <friction>
              <torsional>
                <ode/>
              </torsional>
              <ode/>
            </friction>
          </surface>
        </collision>
        <visual name='visual'>
          <geometry>
            <box>
              <size>0.19 0.19 0.048782</size>
            </box>
          </geometry>
          <material>
            <ambient>0.5 0.3 0.1 1</ambient>
          </material>
        </visual>
        <self_collide>0</self_collide>
        <enable_wind>0</enable_wind>
        <kinematic>0</kinematic>
      </link>
      <pose>0.6 0 0.024391 0 -0 0</pose>
    </model>
    <model name='terrain_block_7_5'>
      <static>1</static>
      <link name='link'>
        <collision name='collision'>
          <geometry>
            <box>
              <size>0.19 0.19 0.034955</size>
            </box>
          </geometry>
          <max_contacts>10</max_contacts>
          <surface>
            <contact>
              <ode/>
            </contact>
            <bounce/>
            <friction>
              <torsional>
                <ode/>
              </torsional>
              <ode/>
            </friction>
          </surface>
        </collision>
        <visual name='visual'>
          <geometry>
            <box>
              <size>0.19 0.19 0.034955</size>
            </box>
          </geometry>
          <material>
            <ambient>0.5 0.3 0.1 1</ambient>
          </material>
        </visual>
        <self_collide>0</self_collide>
        <enable_wind>0</enable_wind>
        <kinematic>0</kinematic>
      </link>
      <pose>0.6 0.2 0.017477 0 -0 0</pose>
    </model>
    <model name='terrain_block_7_6'>
      <static>1</static>
      <link name='link'>
        <collision name='collision'>
          <geometry>
            <box>
              <size>0.19 0.19 0.052267</size>
            </box>
          </geometry>
          <max_contacts>10</max_contacts>
          <surface>
            <contact>
              <ode/>
            </contact>
            <bounce/>
            <friction>
              <torsional>
                <ode/>
              </torsional>
              <ode/>
            </friction>
          </surface>
        </collision>
        <visual name='visual'>
          <geometry>
            <box>
              <size>0.19 0.19 0.052267</size>
            </box>
          </geometry>
          <material>
            <ambient>0.5 0.3 0.1 1</ambient>
          </material>
        </visual>
        <self_collide>0</self_collide>
        <enable_wind>0</enable_wind>
        <kinematic>0</kinematic>
      </link>
      <pose>0.6 0.4 0.026134 0 -0 0</pose>
    </model>
    <model name='terrain_block_7_7'>
      <static>1</static>
      <link name='link'>
        <collision name='collision'>
          <geometry>
            <box>
              <size>0.19 0.19 0.051615</size>
            </box>
          </geometry>
          <max_contacts>10</max_contacts>
          <surface>
            <contact>
              <ode/>
            </contact>
            <bounce/>
            <friction>
              <torsional>
                <ode/>
              </torsional>
              <ode/>
            </friction>
          </surface>
        </collision>
        <visual name='visual'>
          <geometry>
            <box>
              <size>0.19 0.19 0.051615</size>
            </box>
          </geometry>
          <material>
            <ambient>0.5 0.3 0.1 1</ambient>
          </material>
        </visual>
        <self_collide>0</self_collide>
        <enable_wind>0</enable_wind>
        <kinematic>0</kinematic>
      </link>
      <pose>0.6 0.6 0.025807 0 -0 0</pose>
    </model>
    <state world_name='default'>
      <sim_time>72 24000000</sim_time>
      <real_time>80 649364560</real_time>
      <wall_time>1778761343 262417887</wall_time>
      <iterations>72024</iterations>
      <model name='ground_plane'>
        <pose>0 0 0 0 -0 0</pose>
        <scale>1 1 1</scale>
        <link name='link'>
          <pose>0 0 0 0 -0 0</pose>
          <velocity>0 0 0 0 -0 0</velocity>
          <acceleration>0 0 0 0 -0 0</acceleration>
          <wrench>0 0 0 0 -0 0</wrench>
        </link>
      </model>
      <model name='spider_bot'>
        <pose>0.028439 0.016132 0.138992 -0.030502 0.088918 -0.009445</pose>
        <scale>1 1 1</scale>
        <link name='base_link'>
          <pose>0.028439 0.016132 0.138992 -0.030502 0.088918 -0.009445</pose>
          <velocity>0.005544 0.047196 -0.078015 -0.126324 0.036482 0.045122</velocity>
          <acceleration>-1.3e-05 -4e-06 5e-06 0.416139 0.13445 -0.020582</acceleration>
          <wrench>-1.3e-05 -4e-06 5e-06 0 -0 0</wrench>
        </link>
        <link name='l1_c'>
          <pose>0.128714 0.115143 0.127074 0.04553 0.082254 0.827851</pose>
          <velocity>0.000341 0.050185 -0.094318 -0.129956 0.035601 0.002099</velocity>
          <acceleration>-6e-06 -9e-06 9e-06 -1.5e-05 -3.5e-05 3.9e-05</acceleration>
          <wrench>-1e-06 -1e-06 1e-06 0 -0 0</wrench>
        </link>
        <link name='l1_f'>
          <pose>0.155682 0.144502 0.123788 0.05674 -0.643731 0.790028</pose>
          <velocity>-3.3e-05 0.049886 -0.09914 -0.549651 0.424249 0.028427</velocity>
          <acceleration>-6e-06 -7e-06 9e-06 9.1e-05 -4.2e-05 2e-06</acceleration>
          <wrench>-1e-06 -1e-06 1e-06 0 -0 0</wrench>
        </link>
        <link name='l1_t'>
          <pose>0.20072 0.189957 0.171803 0.098225 1.09051 0.91126</pose>
          <velocity>0.018809 0.077836 -0.143188 -0.590847 0.476343 0.03522</velocity>
          <acceleration>-1.2e-05 -1.5e-05 1.2e-05 9.4e-05 -1.5e-05 2e-06</acceleration>
          <wrench>-2e-06 -3e-06 2e-06 0 -0 0</wrench>
        </link>
        <link name='l2_c'>
          <pose>0.029245 0.136075 0.135349 0.091197 0.022789 1.64808</pose>
          <velocity>0.00046 0.046464 -0.09374 -0.131432 0.03413 -0.010101</velocity>
          <acceleration>-5e-06 -4e-06 3e-06 -4e-06 -4.9e-05 -2e-06</acceleration>
          <wrench>-0 -0 0 0 -0 0</wrench>
        </link>
        <link name='l2_f'>
          <pose>0.026156 0.175945 0.134439 0.091779 -0.114628 1.63548</pose>
          <velocity>0.001106 0.046358 -0.099111 -0.131442 0.033757 -0.010491</velocity>
          <acceleration>-5e-06 -4e-06 2e-06 -5e-06 -5e-05 -3e-06</acceleration>
          <wrench>-0 -0 0 0 -0 0</wrench>
        </link>
        <link name='l2_t'>
          <pose>0.021016 0.255254 0.143591 0.272293 1.22541 1.90294</pose>
          <velocity>0.002736 0.047668 -0.109799 -0.278741 0.021813 0.002397</velocity>
          <acceleration>-4e-06 -3e-06 1e-06 -9e-06 -3.2e-05 -1.2e-05</acceleration>
          <wrench>-0 -0 0 0 -0 0</wrench>
        </link>
        <link name='l3_c'>
          <pose>-0.070488 0.117024 0.144834 0.078396 -0.051903 2.47597</pose>
          <velocity>0.001223 0.043448 -0.087178 -0.128625 0.035637 0.017207</velocity>
          <acceleration>-7e-06 2e-06 -1e-06 -7e-06 -4.8e-05 -8e-06</acceleration>
          <wrench>-1e-06 0 -0 0 -0 0</wrench>
        </link>
        <link name='l3_f'>
          <pose>-0.101907 0.141694 0.14691 0.085337 -0.408761 2.44605</pose>
          <velocity>0.000802 0.042934 -0.089364 -0.334384 -0.228932 0.043449</velocity>
          <acceleration>-6e-06 2e-06 -3e-06 -9.4e-05 -0.000127 -9e-06</acceleration>
          <wrench>-1e-06 0 -0 0 -0 0</wrench>
        </link>
        <link name='l3_t'>
          <pose>-0.158263 0.188736 0.178708 0.117589 0.84127 2.56787</pose>
          <velocity>-0.008741 0.050777 -0.118137 -0.401064 -0.309165 0.053798</velocity>
          <acceleration>-1.3e-05 1.1e-05 -1.2e-05 -7.6e-05 -0.000106 -1.9e-05</acceleration>
          <wrench>-3e-06 2e-06 -2e-06 0 -0 0</wrench>
        </link>
        <link name='l4_c'>
          <pose>-0.071833 -0.082878 0.15091 -0.040708 -0.084745 -2.37159</pose>
          <velocity>0.010132 0.04404 -0.062104 -0.12618 0.035941 0.045137</velocity>
          <acceleration>-2e-05 2e-06 2e-06 -2.6e-05 -3.8e-05 -6.3e-05</acceleration>
          <wrench>-2e-06 0 0 0 -0 0</wrench>
        </link>
        <link name='l4_f'>
          <pose>-0.100446 -0.110624 0.154297 -0.041081 -0.159211 -2.36852</pose>
          <velocity>0.011308 0.04313 -0.057689 0.072278 -0.170098 0.03326</velocity>
          <acceleration>-2.1e-05 4e-06 2e-06 5.3e-05 -8.3e-05 -5.6e-05</acceleration>
          <wrench>-2e-06 0 0 0 -0 0</wrench>
        </link>
        <link name='l4_t'>
          <pose>-0.156982 -0.165784 0.16698 -0.054259 0.726707 -2.41109</pose>
          <velocity>0.010837 0.04038 -0.071215 0.20319 -0.300685 0.022666</velocity>
          <acceleration>-2.9e-05 6e-06 -5e-06 4.1e-05 -4.3e-05 -5e-05</acceleration>
          <wrench>-6e-06 1e-06 -1e-06 0 -0 0</wrench>
        </link>
        <link name='l5_c'>
          <pose>0.027631 -0.103816 0.142625 -0.087042 -0.0355 -1.63568</pose>
          <velocity>0.010942 0.048885 -0.060407 -0.135736 0.034515 -0.037253</velocity>
          <acceleration>-2e-05 -4e-06 7e-06 1e-06 -4.8e-05 5.4e-05</acceleration>
          <wrench>-2e-06 -0 1e-06 0 -0 0</wrench>
        </link>
        <link name='l5_f'>
          <pose>0.02504 -0.143711 0.144037 -0.087804 0.136502 -1.65076</pose>
          <velocity>0.009363 0.050054 -0.053345 -0.135774 0.034874 -0.037777</velocity>
          <acceleration>-1.7e-05 -4e-06 7e-06 1e-06 -4.9e-05 5.6e-05</acceleration>
          <wrench>-2e-06 -0 1e-06 0 -0 0</wrench>
        </link>
        <link name='l5_t'>
          <pose>0.01871 -0.222721 0.133138 -0.141166 0.905296 -1.7501</pose>
          <velocity>0.005784 0.050232 -0.039753 0.045096 0.022969 -0.054204</velocity>
          <acceleration>-1.1e-05 -5e-06 6e-06 2.5e-05 -3.3e-05 6.6e-05</acceleration>
          <wrench>-1e-06 -1e-06 1e-06 0 -0 0</wrench>
        </link>
        <link name='l6_c'>
          <pose>0.127361 -0.084763 0.133152 -0.088121 0.03277 -0.894092</pose>
          <velocity>0.010908 0.051401 -0.069453 -0.110103 0.03944 0.204134</velocity>
          <acceleration>-2.3e-05 -1e-05 1.1e-05 -4.1e-05 -5.3e-05 -0.000252</acceleration>
          <wrench>-2e-06 -1e-06 1e-06 0 -0 0</wrench>
        </link>
        <link name='l6_f'>
          <pose>0.152394 -0.115934 0.131842 -0.098759 -0.468712 -0.846477</pose>
          <velocity>0.017857 0.056852 -0.06711 0.247575 0.327227 0.165303</velocity>
          <acceleration>-3.2e-05 -1.8e-05 1.4e-05 -8.7e-05 -3.5e-05 -0.00023</acceleration>
          <wrench>-3e-06 -2e-06 1e-06 0 -0 0</wrench>
        </link>
        <link name='l6_t'>
          <pose>0.199682 -0.169392 0.16798 -0.16401 1.00055 -1.02971</pose>
          <velocity>0.039355 0.056453 -0.095733 0.397661 0.402351 0.167341</velocity>
          <acceleration>-5.1e-05 -2.2e-05 1.7e-05 -9.1e-05 6.8e-05 -0.000256</acceleration>
          <wrench>-1e-05 -4e-06 3e-06 0 -0 0</wrench>
        </link>
      </model>
      <model name='terrain_block_0_0'>
        <pose>-0.8 -0.8 0.015365 0 -0 0</pose>
        <scale>1 1 1</scale>
        <link name='link'>
          <pose>-0.8 -0.8 0.015365 0 -0 0</pose>
          <velocity>0 0 0 0 -0 0</velocity>
          <acceleration>0 0 0 0 -0 0</acceleration>
          <wrench>0 0 0 0 -0 0</wrench>
        </link>
      </model>
      <model name='terrain_block_0_1'>
        <pose>-0.8 -0.6 0.013998 0 -0 0</pose>
        <scale>1 1 1</scale>
        <link name='link'>
          <pose>-0.8 -0.6 0.013998 0 -0 0</pose>
          <velocity>0 0 0 0 -0 0</velocity>
          <acceleration>0 0 0 0 -0 0</acceleration>
          <wrench>0 0 0 0 -0 0</wrench>
        </link>
      </model>
      <model name='terrain_block_0_2'>
        <pose>-0.8 -0.4 0.028844 0 -0 0</pose>
        <scale>1 1 1</scale>
        <link name='link'>
          <pose>-0.8 -0.4 0.028844 0 -0 0</pose>
          <velocity>0 0 0 0 -0 0</velocity>
          <acceleration>0 0 0 0 -0 0</acceleration>
          <wrench>0 0 0 0 -0 0</wrench>
        </link>
      </model>
      <model name='terrain_block_0_3'>
        <pose>-0.8 -0.2 0.021559 0 -0 0</pose>
        <scale>1 1 1</scale>
        <link name='link'>
          <pose>-0.8 -0.2 0.021559 0 -0 0</pose>
          <velocity>0 0 0 0 -0 0</velocity>
          <acceleration>0 0 0 0 -0 0</acceleration>
          <wrench>0 0 0 0 -0 0</wrench>
        </link>
      </model>
      <model name='terrain_block_0_4'>
        <pose>-0.8 0 0.033177 0 -0 0</pose>
        <scale>1 1 1</scale>
        <link name='link'>
          <pose>-0.8 0 0.033177 0 -0 0</pose>
          <velocity>0 0 0 0 -0 0</velocity>
          <acceleration>0 0 0 0 -0 0</acceleration>
          <wrench>0 0 0 0 -0 0</wrench>
        </link>
      </model>
      <model name='terrain_block_0_5'>
        <pose>-0.8 0.2 0.033546 0 -0 0</pose>
        <scale>1 1 1</scale>
        <link name='link'>
          <pose>-0.8 0.2 0.033546 0 -0 0</pose>
          <velocity>0 0 0 0 -0 0</velocity>
          <acceleration>0 0 0 0 -0 0</acceleration>
          <wrench>0 0 0 0 -0 0</wrench>
        </link>
      </model>
      <model name='terrain_block_0_6'>
        <pose>-0.8 0.4 0.03142 0 -0 0</pose>
        <scale>1 1 1</scale>
        <link name='link'>
          <pose>-0.8 0.4 0.03142 0 -0 0</pose>
          <velocity>0 0 0 0 -0 0</velocity>
          <acceleration>0 0 0 0 -0 0</acceleration>
          <wrench>0 0 0 0 -0 0</wrench>
        </link>
      </model>
      <model name='terrain_block_0_7'>
        <pose>-0.8 0.6 0.012788 0 -0 0</pose>
        <scale>1 1 1</scale>
        <link name='link'>
          <pose>-0.8 0.6 0.012788 0 -0 0</pose>
          <velocity>0 0 0 0 -0 0</velocity>
          <acceleration>0 0 0 0 -0 0</acceleration>
          <wrench>0 0 0 0 -0 0</wrench>
        </link>
      </model>
      <model name='terrain_block_1_0'>
        <pose>-0.6 -0.8 0.012611 0 -0 0</pose>
        <scale>1 1 1</scale>
        <link name='link'>
          <pose>-0.6 -0.8 0.012611 0 -0 0</pose>
          <velocity>0 0 0 0 -0 0</velocity>
          <acceleration>0 0 0 0 -0 0</acceleration>
          <wrench>0 0 0 0 -0 0</wrench>
        </link>
      </model>
      <model name='terrain_block_1_1'>
        <pose>-0.6 -0.6 0.026009 0 -0 0</pose>
        <scale>1 1 1</scale>
        <link name='link'>
          <pose>-0.6 -0.6 0.026009 0 -0 0</pose>
          <velocity>0 0 0 0 -0 0</velocity>
          <acceleration>0 0 0 0 -0 0</acceleration>
          <wrench>0 0 0 0 -0 0</wrench>
        </link>
      </model>
      <model name='terrain_block_1_2'>
        <pose>-0.6 -0.4 0.023969 0 -0 0</pose>
        <scale>1 1 1</scale>
        <link name='link'>
          <pose>-0.6 -0.4 0.023969 0 -0 0</pose>
          <velocity>0 0 0 0 -0 0</velocity>
          <acceleration>0 0 0 0 -0 0</acceleration>
          <wrench>0 0 0 0 -0 0</wrench>
        </link>
      </model>
      <model name='terrain_block_1_3'>
        <pose>-0.6 -0.2 0.014751 0 -0 0</pose>
        <scale>1 1 1</scale>
        <link name='link'>
          <pose>-0.6 -0.2 0.014751 0 -0 0</pose>
          <velocity>0 0 0 0 -0 0</velocity>
          <acceleration>0 0 0 0 -0 0</acceleration>
          <wrench>0 0 0 0 -0 0</wrench>
        </link>
      </model>
      <model name='terrain_block_1_4'>
        <pose>-0.6 0 0.02991 0 -0 0</pose>
        <scale>1 1 1</scale>
        <link name='link'>
          <pose>-0.6 0 0.02991 0 -0 0</pose>
          <velocity>0 0 0 0 -0 0</velocity>
          <acceleration>0 0 0 0 -0 0</acceleration>
          <wrench>0 0 0 0 -0 0</wrench>
        </link>
      </model>
      <model name='terrain_block_1_5'>
        <pose>-0.6 0.2 0.020995 0 -0 0</pose>
        <scale>1 1 1</scale>
        <link name='link'>
          <pose>-0.6 0.2 0.020995 0 -0 0</pose>
          <velocity>0 0 0 0 -0 0</velocity>
          <acceleration>0 0 0 0 -0 0</acceleration>
          <wrench>0 0 0 0 -0 0</wrench>
        </link>
      </model>
      <model name='terrain_block_1_6'>
        <pose>-0.6 0.4 0.026259 0 -0 0</pose>
        <scale>1 1 1</scale>
        <link name='link'>
          <pose>-0.6 0.4 0.026259 0 -0 0</pose>
          <velocity>0 0 0 0 -0 0</velocity>
          <acceleration>0 0 0 0 -0 0</acceleration>
          <wrench>0 0 0 0 -0 0</wrench>
        </link>
      </model>
      <model name='terrain_block_1_7'>
        <pose>-0.6 0.6 0.011272 0 -0 0</pose>
        <scale>1 1 1</scale>
        <link name='link'>
          <pose>-0.6 0.6 0.011272 0 -0 0</pose>
          <velocity>0 0 0 0 -0 0</velocity>
          <acceleration>0 0 0 0 -0 0</acceleration>
          <wrench>0 0 0 0 -0 0</wrench>
        </link>
      </model>
      <model name='terrain_block_2_0'>
        <pose>-0.4 -0.8 0.010016 0 -0 0</pose>
        <scale>1 1 1</scale>
        <link name='link'>
          <pose>-0.4 -0.8 0.010016 0 -0 0</pose>
          <velocity>0 0 0 0 -0 0</velocity>
          <acceleration>0 0 0 0 -0 0</acceleration>
          <wrench>0 0 0 0 -0 0</wrench>
        </link>
      </model>
      <model name='terrain_block_2_1'>
        <pose>-0.4 -0.6 0.017833 0 -0 0</pose>
        <scale>1 1 1</scale>
        <link name='link'>
          <pose>-0.4 -0.6 0.017833 0 -0 0</pose>
          <velocity>0 0 0 0 -0 0</velocity>
          <acceleration>0 0 0 0 -0 0</acceleration>
          <wrench>0 0 0 0 -0 0</wrench>
        </link>
      </model>
      <model name='terrain_block_2_2'>
        <pose>-0.4 -0.4 0.031071 0 -0 0</pose>
        <scale>1 1 1</scale>
        <link name='link'>
          <pose>-0.4 -0.4 0.031071 0 -0 0</pose>
          <velocity>0 0 0 0 -0 0</velocity>
          <acceleration>0 0 0 0 -0 0</acceleration>
          <wrench>0 0 0 0 -0 0</wrench>
        </link>
      </model>
      <model name='terrain_block_2_3'>
        <pose>-0.4 -0.2 0.011332 0 -0 0</pose>
        <scale>1 1 1</scale>
        <link name='link'>
          <pose>-0.4 -0.2 0.011332 0 -0 0</pose>
          <velocity>0 0 0 0 -0 0</velocity>
          <acceleration>0 0 0 0 -0 0</acceleration>
          <wrench>0 0 0 0 -0 0</wrench>
        </link>
      </model>
      <model name='terrain_block_2_4'>
        <pose>-0.4 0 0.0147 0 -0 0</pose>
        <scale>1 1 1</scale>
        <link name='link'>
          <pose>-0.4 0 0.0147 0 -0 0</pose>
          <velocity>0 0 0 0 -0 0</velocity>
          <acceleration>0 0 0 0 -0 0</acceleration>
          <wrench>0 0 0 0 -0 0</wrench>
        </link>
      </model>
      <model name='terrain_block_2_5'>
        <pose>-0.4 0.2 0.031978 0 -0 0</pose>
        <scale>1 1 1</scale>
        <link name='link'>
          <pose>-0.4 0.2 0.031978 0 -0 0</pose>
          <velocity>0 0 0 0 -0 0</velocity>
          <acceleration>0 0 0 0 -0 0</acceleration>
          <wrench>0 0 0 0 -0 0</wrench>
        </link>
      </model>
      <model name='terrain_block_2_6'>
        <pose>-0.4 0.4 0.026065 0 -0 0</pose>
        <scale>1 1 1</scale>
        <link name='link'>
          <pose>-0.4 0.4 0.026065 0 -0 0</pose>
          <velocity>0 0 0 0 -0 0</velocity>
          <acceleration>0 0 0 0 -0 0</acceleration>
          <wrench>0 0 0 0 -0 0</wrench>
        </link>
      </model>
      <model name='terrain_block_2_7'>
        <pose>-0.4 0.6 0.015127 0 -0 0</pose>
        <scale>1 1 1</scale>
        <link name='link'>
          <pose>-0.4 0.6 0.015127 0 -0 0</pose>
          <velocity>0 0 0 0 -0 0</velocity>
          <acceleration>0 0 0 0 -0 0</acceleration>
          <wrench>0 0 0 0 -0 0</wrench>
        </link>
      </model>
      <model name='terrain_block_3_0'>
        <pose>-0.2 -0.8 0.012928 0 -0 0</pose>
        <scale>1 1 1</scale>
        <link name='link'>
          <pose>-0.2 -0.8 0.012928 0 -0 0</pose>
          <velocity>0 0 0 0 -0 0</velocity>
          <acceleration>0 0 0 0 -0 0</acceleration>
          <wrench>0 0 0 0 -0 0</wrench>
        </link>
      </model>
      <model name='terrain_block_3_1'>
        <pose>-0.2 -0.6 0.032292 0 -0 0</pose>
        <scale>1 1 1</scale>
        <link name='link'>
          <pose>-0.2 -0.6 0.032292 0 -0 0</pose>
          <velocity>0 0 0 0 -0 0</velocity>
          <acceleration>0 0 0 0 -0 0</acceleration>
          <wrench>0 0 0 0 -0 0</wrench>
        </link>
      </model>
      <model name='terrain_block_3_2'>
        <pose>-0.2 -0.4 0.015369 0 -0 0</pose>
        <scale>1 1 1</scale>
        <link name='link'>
          <pose>-0.2 -0.4 0.015369 0 -0 0</pose>
          <velocity>0 0 0 0 -0 0</velocity>
          <acceleration>0 0 0 0 -0 0</acceleration>
          <wrench>0 0 0 0 -0 0</wrench>
        </link>
      </model>
      <model name='terrain_block_3_3'>
        <pose>-0.2 -0.2 0.030428 0 -0 0</pose>
        <scale>1 1 1</scale>
        <link name='link'>
          <pose>-0.2 -0.2 0.030428 0 -0 0</pose>
          <velocity>0 0 0 0 -0 0</velocity>
          <acceleration>0 0 0 0 -0 0</acceleration>
          <wrench>0 0 0 0 -0 0</wrench>
        </link>
      </model>
      <model name='terrain_block_3_4'>
        <pose>-0.2 0 0.01482 0 -0 0</pose>
        <scale>1 1 1</scale>
        <link name='link'>
          <pose>-0.2 0 0.01482 0 -0 0</pose>
          <velocity>0 0 0 0 -0 0</velocity>
          <acceleration>0 0 0 0 -0 0</acceleration>
          <wrench>0 0 0 0 -0 0</wrench>
        </link>
      </model>
      <model name='terrain_block_3_5'>
        <pose>-0.2 0.2 0.032331 0 -0 0</pose>
        <scale>1 1 1</scale>
        <link name='link'>
          <pose>-0.2 0.2 0.032331 0 -0 0</pose>
          <velocity>0 0 0 0 -0 0</velocity>
          <acceleration>0 0 0 0 -0 0</acceleration>
          <wrench>0 0 0 0 -0 0</wrench>
        </link>
      </model>
      <model name='terrain_block_3_6'>
        <pose>-0.2 0.4 0.026472 0 -0 0</pose>
        <scale>1 1 1</scale>
        <link name='link'>
          <pose>-0.2 0.4 0.026472 0 -0 0</pose>
          <velocity>0 0 0 0 -0 0</velocity>
          <acceleration>0 0 0 0 -0 0</acceleration>
          <wrench>0 0 0 0 -0 0</wrench>
        </link>
      </model>
      <model name='terrain_block_3_7'>
        <pose>-0.2 0.6 0.02103 0 -0 0</pose>
        <scale>1 1 1</scale>
        <link name='link'>
          <pose>-0.2 0.6 0.02103 0 -0 0</pose>
          <velocity>0 0 0 0 -0 0</velocity>
          <acceleration>0 0 0 0 -0 0</acceleration>
          <wrench>0 0 0 0 -0 0</wrench>
        </link>
      </model>
      <model name='terrain_block_4_0'>
        <pose>0 -0.8 0.028107 0 -0 0</pose>
        <scale>1 1 1</scale>
        <link name='link'>
          <pose>0 -0.8 0.028107 0 -0 0</pose>
          <velocity>0 0 0 0 -0 0</velocity>
          <acceleration>0 0 0 0 -0 0</acceleration>
          <wrench>0 0 0 0 -0 0</wrench>
        </link>
      </model>
      <model name='terrain_block_4_1'>
        <pose>0 -0.6 0.02757 0 -0 0</pose>
        <scale>1 1 1</scale>
        <link name='link'>
          <pose>0 -0.6 0.02757 0 -0 0</pose>
          <velocity>0 0 0 0 -0 0</velocity>
          <acceleration>0 0 0 0 -0 0</acceleration>
          <wrench>0 0 0 0 -0 0</wrench>
        </link>
      </model>
      <model name='terrain_block_4_2'>
        <pose>0 -0.4 0.027678 0 -0 0</pose>
        <scale>1 1 1</scale>
        <link name='link'>
          <pose>0 -0.4 0.027678 0 -0 0</pose>
          <velocity>0 0 0 0 -0 0</velocity>
          <acceleration>0 0 0 0 -0 0</acceleration>
          <wrench>0 0 0 0 -0 0</wrench>
        </link>
      </model>
      <model name='terrain_block_4_3'>
        <pose>0 -0.2 0.026613 0 -0 0</pose>
        <scale>1 1 1</scale>
        <link name='link'>
          <pose>0 -0.2 0.026613 0 -0 0</pose>
          <velocity>0 0 0 0 -0 0</velocity>
          <acceleration>0 0 0 0 -0 0</acceleration>
          <wrench>0 0 0 0 -0 0</wrench>
        </link>
      </model>
      <model name='terrain_block_4_4'>
        <pose>0 0 0.021934 0 -0 0</pose>
        <scale>1 1 1</scale>
        <link name='link'>
          <pose>0 0 0.021934 0 -0 0</pose>
          <velocity>0 0 0 0 -0 0</velocity>
          <acceleration>0 0 0 0 -0 0</acceleration>
          <wrench>0 0 0 0 -0 0</wrench>
        </link>
      </model>
      <model name='terrain_block_4_5'>
        <pose>0 0.2 0.016834 0 -0 0</pose>
        <scale>1 1 1</scale>
        <link name='link'>
          <pose>0 0.2 0.016834 0 -0 0</pose>
          <velocity>0 0 0 0 -0 0</velocity>
          <acceleration>0 0 0 0 -0 0</acceleration>
          <wrench>0 0 0 0 -0 0</wrench>
        </link>
      </model>
      <model name='terrain_block_4_6'>
        <pose>0 0.4 0.023674 0 -0 0</pose>
        <scale>1 1 1</scale>
        <link name='link'>
          <pose>0 0.4 0.023674 0 -0 0</pose>
          <velocity>0 0 0 0 -0 0</velocity>
          <acceleration>0 0 0 0 -0 0</acceleration>
          <wrench>0 0 0 0 -0 0</wrench>
        </link>
      </model>
      <model name='terrain_block_4_7'>
        <pose>0 0.6 0.012086 0 -0 0</pose>
        <scale>1 1 1</scale>
        <link name='link'>
          <pose>0 0.6 0.012086 0 -0 0</pose>
          <velocity>0 0 0 0 -0 0</velocity>
          <acceleration>0 0 0 0 -0 0</acceleration>
          <wrench>0 0 0 0 -0 0</wrench>
        </link>
      </model>
      <model name='terrain_block_5_0'>
        <pose>0.2 -0.8 0.014721 0 -0 0</pose>
        <scale>1 1 1</scale>
        <link name='link'>
          <pose>0.2 -0.8 0.014721 0 -0 0</pose>
          <velocity>0 0 0 0 -0 0</velocity>
          <acceleration>0 0 0 0 -0 0</acceleration>
          <wrench>0 0 0 0 -0 0</wrench>
        </link>
      </model>
      <model name='terrain_block_5_1'>
        <pose>0.2 -0.6 0.022647 0 -0 0</pose>
        <scale>1 1 1</scale>
        <link name='link'>
          <pose>0.2 -0.6 0.022647 0 -0 0</pose>
          <velocity>0 0 0 0 -0 0</velocity>
          <acceleration>0 0 0 0 -0 0</acceleration>
          <wrench>0 0 0 0 -0 0</wrench>
        </link>
      </model>
      <model name='terrain_block_5_2'>
        <pose>0.2 -0.4 0.012844 0 -0 0</pose>
        <scale>1 1 1</scale>
        <link name='link'>
          <pose>0.2 -0.4 0.012844 0 -0 0</pose>
          <velocity>0 0 0 0 -0 0</velocity>
          <acceleration>0 0 0 0 -0 0</acceleration>
          <wrench>0 0 0 0 -0 0</wrench>
        </link>
      </model>
      <model name='terrain_block_5_3'>
        <pose>0.2 -0.2 0.021375 0 -0 0</pose>
        <scale>1 1 1</scale>
        <link name='link'>
          <pose>0.2 -0.2 0.021375 0 -0 0</pose>
          <velocity>0 0 0 0 -0 0</velocity>
          <acceleration>0 0 0 0 -0 0</acceleration>
          <wrench>0 0 0 0 -0 0</wrench>
        </link>
      </model>
      <model name='terrain_block_5_4'>
        <pose>0.2 0 0.017914 0 -0 0</pose>
        <scale>1 1 1</scale>
        <link name='link'>
          <pose>0.2 0 0.017914 0 -0 0</pose>
          <velocity>0 0 0 0 -0 0</velocity>
          <acceleration>0 0 0 0 -0 0</acceleration>
          <wrench>0 0 0 0 -0 0</wrench>
        </link>
      </model>
      <model name='terrain_block_5_5'>
        <pose>0.2 0.2 0.022425 0 -0 0</pose>
        <scale>1 1 1</scale>
        <link name='link'>
          <pose>0.2 0.2 0.022425 0 -0 0</pose>
          <velocity>0 0 0 0 -0 0</velocity>
          <acceleration>0 0 0 0 -0 0</acceleration>
          <wrench>0 0 0 0 -0 0</wrench>
        </link>
      </model>
      <model name='terrain_block_5_6'>
        <pose>0.2 0.4 0.022097 0 -0 0</pose>
        <scale>1 1 1</scale>
        <link name='link'>
          <pose>0.2 0.4 0.022097 0 -0 0</pose>
          <velocity>0 0 0 0 -0 0</velocity>
          <acceleration>0 0 0 0 -0 0</acceleration>
          <wrench>0 0 0 0 -0 0</wrench>
        </link>
      </model>
      <model name='terrain_block_5_7'>
        <pose>0.2 0.6 0.023192 0 -0 0</pose>
        <scale>1 1 1</scale>
        <link name='link'>
          <pose>0.2 0.6 0.023192 0 -0 0</pose>
          <velocity>0 0 0 0 -0 0</velocity>
          <acceleration>0 0 0 0 -0 0</acceleration>
          <wrench>0 0 0 0 -0 0</wrench>
        </link>
      </model>
      <model name='terrain_block_6_0'>
        <pose>0.4 -0.8 0.031363 0 -0 0</pose>
        <scale>1 1 1</scale>
        <link name='link'>
          <pose>0.4 -0.8 0.031363 0 -0 0</pose>
          <velocity>0 0 0 0 -0 0</velocity>
          <acceleration>0 0 0 0 -0 0</acceleration>
          <wrench>0 0 0 0 -0 0</wrench>
        </link>
      </model>
      <model name='terrain_block_6_1'>
        <pose>0.4 -0.6 0.01743 0 -0 0</pose>
        <scale>1 1 1</scale>
        <link name='link'>
          <pose>0.4 -0.6 0.01743 0 -0 0</pose>
          <velocity>0 0 0 0 -0 0</velocity>
          <acceleration>0 0 0 0 -0 0</acceleration>
          <wrench>0 0 0 0 -0 0</wrench>
        </link>
      </model>
      <model name='terrain_block_6_2'>
        <pose>0.4 -0.4 0.023655 0 -0 0</pose>
        <scale>1 1 1</scale>
        <link name='link'>
          <pose>0.4 -0.4 0.023655 0 -0 0</pose>
          <velocity>0 0 0 0 -0 0</velocity>
          <acceleration>0 0 0 0 -0 0</acceleration>
          <wrench>0 0 0 0 -0 0</wrench>
        </link>
      </model>
      <model name='terrain_block_6_3'>
        <pose>0.4 -0.2 0.034733 0 -0 0</pose>
        <scale>1 1 1</scale>
        <link name='link'>
          <pose>0.4 -0.2 0.034733 0 -0 0</pose>
          <velocity>0 0 0 0 -0 0</velocity>
          <acceleration>0 0 0 0 -0 0</acceleration>
          <wrench>0 0 0 0 -0 0</wrench>
        </link>
      </model>
      <model name='terrain_block_6_4'>
        <pose>0.4 0 0.012916 0 -0 0</pose>
        <scale>1 1 1</scale>
        <link name='link'>
          <pose>0.4 0 0.012916 0 -0 0</pose>
          <velocity>0 0 0 0 -0 0</velocity>
          <acceleration>0 0 0 0 -0 0</acceleration>
          <wrench>0 0 0 0 -0 0</wrench>
        </link>
      </model>
      <model name='terrain_block_6_5'>
        <pose>0.4 0.2 0.03177 0 -0 0</pose>
        <scale>1 1 1</scale>
        <link name='link'>
          <pose>0.4 0.2 0.03177 0 -0 0</pose>
          <velocity>0 0 0 0 -0 0</velocity>
          <acceleration>0 0 0 0 -0 0</acceleration>
          <wrench>0 0 0 0 -0 0</wrench>
        </link>
      </model>
      <model name='terrain_block_6_6'>
        <pose>0.4 0.4 0.029324 0 -0 0</pose>
        <scale>1 1 1</scale>
        <link name='link'>
          <pose>0.4 0.4 0.029324 0 -0 0</pose>
          <velocity>0 0 0 0 -0 0</velocity>
          <acceleration>0 0 0 0 -0 0</acceleration>
          <wrench>0 0 0 0 -0 0</wrench>
        </link>
      </model>
      <model name='terrain_block_6_7'>
        <pose>0.4 0.6 0.014052 0 -0 0</pose>
        <scale>1 1 1</scale>
        <link name='link'>
          <pose>0.4 0.6 0.014052 0 -0 0</pose>
          <velocity>0 0 0 0 -0 0</velocity>
          <acceleration>0 0 0 0 -0 0</acceleration>
          <wrench>0 0 0 0 -0 0</wrench>
        </link>
      </model>
      <model name='terrain_block_7_0'>
        <pose>0.6 -0.8 0.012205 0 -0 0</pose>
        <scale>1 1 1</scale>
        <link name='link'>
          <pose>0.6 -0.8 0.012205 0 -0 0</pose>
          <velocity>0 0 0 0 -0 0</velocity>
          <acceleration>0 0 0 0 -0 0</acceleration>
          <wrench>0 0 0 0 -0 0</wrench>
        </link>
      </model>
      <model name='terrain_block_7_1'>
        <pose>0.6 -0.6 0.031193 0 -0 0</pose>
        <scale>1 1 1</scale>
        <link name='link'>
          <pose>0.6 -0.6 0.031193 0 -0 0</pose>
          <velocity>0 0 0 0 -0 0</velocity>
          <acceleration>0 0 0 0 -0 0</acceleration>
          <wrench>0 0 0 0 -0 0</wrench>
        </link>
      </model>
      <model name='terrain_block_7_2'>
        <pose>0.6 -0.4 0.03299 0 -0 0</pose>
        <scale>1 1 1</scale>
        <link name='link'>
          <pose>0.6 -0.4 0.03299 0 -0 0</pose>
          <velocity>0 0 0 0 -0 0</velocity>
          <acceleration>0 0 0 0 -0 0</acceleration>
          <wrench>0 0 0 0 -0 0</wrench>
        </link>
      </model>
      <model name='terrain_block_7_3'>
        <pose>0.6 -0.2 0.033962 0 -0 0</pose>
        <scale>1 1 1</scale>
        <link name='link'>
          <pose>0.6 -0.2 0.033962 0 -0 0</pose>
          <velocity>0 0 0 0 -0 0</velocity>
          <acceleration>0 0 0 0 -0 0</acceleration>
          <wrench>0 0 0 0 -0 0</wrench>
        </link>
      </model>
      <model name='terrain_block_7_4'>
        <pose>0.6 0 0.024391 0 -0 0</pose>
        <scale>1 1 1</scale>
        <link name='link'>
          <pose>0.6 0 0.024391 0 -0 0</pose>
          <velocity>0 0 0 0 -0 0</velocity>
          <acceleration>0 0 0 0 -0 0</acceleration>
          <wrench>0 0 0 0 -0 0</wrench>
        </link>
      </model>
      <model name='terrain_block_7_5'>
        <pose>0.6 0.2 0.017477 0 -0 0</pose>
        <scale>1 1 1</scale>
        <link name='link'>
          <pose>0.6 0.2 0.017477 0 -0 0</pose>
          <velocity>0 0 0 0 -0 0</velocity>
          <acceleration>0 0 0 0 -0 0</acceleration>
          <wrench>0 0 0 0 -0 0</wrench>
        </link>
      </model>
      <model name='terrain_block_7_6'>
        <pose>0.6 0.4 0.026134 0 -0 0</pose>
        <scale>1 1 1</scale>
        <link name='link'>
          <pose>0.6 0.4 0.026134 0 -0 0</pose>
          <velocity>0 0 0 0 -0 0</velocity>
          <acceleration>0 0 0 0 -0 0</acceleration>
          <wrench>0 0 0 0 -0 0</wrench>
        </link>
      </model>
      <model name='terrain_block_7_7'>
        <pose>0.6 0.6 0.025807 0 -0 0</pose>
        <scale>1 1 1</scale>
        <link name='link'>
          <pose>0.6 0.6 0.025807 0 -0 0</pose>
          <velocity>0 0 0 0 -0 0</velocity>
          <acceleration>0 0 0 0 -0 0</acceleration>
          <wrench>0 0 0 0 -0 0</wrench>
        </link>
      </model>
      <light name='sun'>
        <pose>0 0 10 0 -0 0</pose>
      </light>
    </state>
    <gui fullscreen='0'>
      <camera name='user_camera'>
        <pose>2.46606 -1.26974 1.72869 0 0.519643 2.52819</pose>
        <view_controller>orbit</view_controller>
        <projection_type>perspective</projection_type>
      </camera>
    </gui>
  </world>
</sdf>
